Workbook

Sheet Proyectos
A2: Contrato | B2: Compañias | C2: Campos | E2: id | F2: idConsecutivo | G2: number | H2: id_contrato | I2: id_oilfield | J2: id_active | K2: name | L2: year | M2: diameter | N2: length | O2: description | P2: priority | Q2: budgetmanagement | R2: linerigth | S2: government | T2: receivedenginnering | U2: datedelivery | V2: supplypipe | W2: request | X2: programstart | Y2: programend | Z2: bestprojectedstart | AA2: bestprojectedend | AB2: classification | AC2: state | AD2: typeconstruction | AE2: comment
A3: 640852805 | B3: ARENDAL | C3: Akal | E3: 1 | F3: 190 | G3: S/N | H3: 78 | I3: 20 | J3: 1 | K3: IPC en GSD 8" Ø X 8.2 km de PP-Akal-B-1 | L3: 2024 | M3: 0 | N3: 0 | O3: Ingeniería, Procura, Construcción de un Gasoducto de 8”Ø x 8.2 km de PP-Akal-B-1 hacia PP-Ek-A; By Pass submarino de 20”Ø x 0.2 km. | P3: 1 | Q3: NO | R3: NO | S3: NO | T3: NO | U3: NULL | V3: NULL | W3: NULL | X3: 44637 | Z3: 45588 | AA3: 45596 | AB3: Marina | AC3: Ejecucion | AD3: Ducto Marino | AE3: NULL
A4: 640852806 | B4: DEMAR | C4: Yaxché | E4: 2 | F4: 201 | G4: S/N | H4: 79 | I4: 18 | J4: 1 | K4: GSD de BN 16”Ø x 20 Km Yaxché-A hacia Tlacame-A | L4: 2024 | M4: 0 | N4: 0 | O4: GSD de BN 16”Ø x 20 Km Yaxché-A hacia Tlacame-A | P4: 1 | Q4: NO | R4: NO | S4: NO | T4: NO | U4: NULL | V4: NULL | W4: NULL | X4: 44652 | Y4: 44891 | Z4: 45509 | AA4: 45534 | AB4: Marina | AC4: Ejecucion | AD4: Ducto Marino | AE4: NULL
A5: 640852806 | B5: DEMAR | C5: Tlacame | E5: 3 | F5: 202 | G5: S/N | H5: 79 | I5: 14 | J5: 1 | K5: OGD de 20”Ø x 8.8 Km Mulach-A hacia Interc. Subm. con OGD Tlacame-A / Xanab-C | L5: 2024 | M5: 0 | N5: 0 | O5: OGD de 20”Ø x 8.8 Km Mulach-A hacia Interc. Subm. con OGD Tlacame-A / Xanab-C | P5: 1 | Q5: NO | R5: NO | S5: NO | T5: NO | U5: NULL | V5: NULL | W5: NULL | X5: 44652 | Y5: 44871 | Z5: 44993 | AA5: 45534 | AB5: Marina | AC5: Ejecucion | AD5: Ducto Marino | AE5: NULL
A6: 640852806 | B6: DEMAR | C6: Tlacame | E6: 4 | F6: 203 | G6: S/N | H6: 79 | I6: 14 | J6: 1 | K6: GSD de BN 16”Ø x 0.5 Km Interc. Subm. con OGD de 16” Tlacame-A hacia Mulach-A | L6: 2024 | M6: 0 | N6: 0 | O6: GSD de BN 16”Ø x 0.5 Km Interc. Subm. con OGD de 16” Tlacame-A hacia Mulach-A | P6: 1 | Q6: NO | R6: NO | S6: NO | T6: NO | U6: NULL | V6: NULL | W6: NULL | X6: 44652 | Y6: 44851 | Z6: 44931 | AA6: 45534 | AB6: Marina | AC6: Ejecucion | AD6: Ducto Marino | AE6: NULL
A7: 640852806 | B7: DEMAR | C7: Tlacame | E7: 5 | F7: 204 | G7: S/N | H7: 79 | I7: 14 | J7: 1 | K7: OGD de 16”Ø x 6.8 Km de la plataforma Xanab-201 hacia la plataforma Xanab-D | L7: 2024 | M7: 0 | N7: 0 | O7: OGD de 16”Ø x 6.8 Km de la plataforma Xanab-201 hacia la plataforma Xanab-D | P7: 1 | Q7: NO | R7: NO | S7: NO | T7: NO | U7: NULL | V7: NULL | W7: NULL | X7: 45092 | Y7: 45295 | Z7: 45550 | AA7: 45576 | AB7: Marina | AC7: Ejecucion | AD7: Ducto Marino | AE7: NULL
A8: 640852818 | B8: PERMADUCTO | C8: Xanab | E8: 6 | F8: 210 | G8: S/N | H8: 72 | I8: 17 | J8: 1 | K8: Plataforma Recuperadora de Pozos tipo Típode Xanab-201 | L8: 2024 | M8: 0 | N8: 0 | O8: Plataforma Recuperadora de Pozos tipo Típode Xanab-201 | P8: 1 | Q8: NO | R8: NO | S8: NO | T8: NO | U8: NULL | V8: NULL | W8: NULL | X8: 45128 | Y8: 45364 | Z8: 45525 | AA8: 45545 | AB8: Marina | AC8: Ejecucion | AD8: Plataforma | AE8: NULL
A9: 640852818 | B9: PERMADUCTO | C9: Yaxché | E9: 7 | F9: 211 | G9: S/N | H9: 72 | I9: 18 | J9: 1 | K9: Plataforma de Inyección de Agua de Mar Yaxche-AI | L9: 2024 | M9: 0 | N9: 0 | O9: Plataforma de Inyección de Agua de Mar Yaxche-AI | P9: 1 | Q9: NO | R9: NO | S9: NO | T9: NO | U9: NULL | V9: NULL | W9: NULL | X9: 44797 | Y9: 45286 | Z9: 45535 | AA9: 45561 | AB9: Marina | AC9: Ejecucion | AD9: Plataforma | AE9: NULL
A10: 640853826 | B10: ESEASA | C10: Pokche | E10: 8 | F10: 212 | G10: S/N | H10: 73 | I10: 21 | J10: 1 | K10: EMDR-1-POKCHE-NE | L10: 2024 | M10: 0 | N10: 0 | O10: EMDR-1-POKCHE-NE | P10: 1 | Q10: NO | R10: NO | S10: NO | T10: NO | U10: NULL | V10: NULL | W10: NULL | X10: 45090 | Y10: 45299 | Z10: 45409 | AA10: 45511 | AB10: Marina | AC10: Ejecucion | AD10: Plataforma | AE10: NULL
A11: 640853826 | B11: ESEASA | C11: Tentok | E11: 9 | F11: 213 | G11: S/N | H11: 73 | I11: 22 | J11: 1 | K11: EMDR-2 TENTOK | L11: 2024 | M11: 0 | N11: 0 | O11: EMDR-2 TENTOK | P11: 1 | Q11: NO | R11: NO | S11: NO | T11: NO | U11: NULL | V11: NULL | W11: NULL | X11: 45090 | Y11: 45299 | Z11: 45485 | AA11: 45511 | AB11: Marina | AC11: Ejecucion | AD11: Plataforma | AE11: NULL
A12: 640853827 | B12: ESEASA | C12: MACUIL | E12: 10 | F12: 214 | G12: S/N | H12: 74 | I12: 10 | J12: 1 | K12: EMTR-1 ( EX TENTOK) | L12: 2024 | M12: 0 | N12: 0 | O12: EMTR-1 ( EX TENTOK) | P12: 1 | Q12: NO | R12: NO | S12: NO | T12: NO | U12: NULL | V12: NULL | W12: NULL | X12: 45090 | Y12: 45282 | AB12: Marina | AC12: Ejecucion | AD12: Plataforma | AE12: NULL
A13: 640853827 | B13: ESEASA | C13: MACUIL | E13: 11 | F13: 215 | G13: S/N | H13: 74 | I13: 10 | J13: 1 | K13: EMTR-2 MACUIL | L13: 2024 | M13: 0 | N13: 0 | O13: EMTR-2 MACUIL | P13: 1 | Q13: NO | R13: NO | S13: NO | T13: NO | U13: NULL | V13: NULL | W13: NULL | X13: 45090 | Y13: 45282 | AB13: Marina | AC13: Ejecucion | AD13: Plataforma | AE13: NULL
A14: 640853827 | B14: ESEASA | C14: ATOYATL | E14: 12 | F14: 216 | G14: S/N | H14: 74 | I14: 6 | J14: 1 | K14: EMTR-3 ATOYATL | L14: 2024 | M14: 0 | N14: 0 | O14: EMTR-3 ATOYATL | P14: 1 | Q14: NO | R14: NO | S14: NO | T14: NO | U14: NULL | V14: NULL | W14: NULL | X14: 45090 | Y14: 45346 | Z14: 45453 | AA14: 45514 | AB14: Marina | AC14: Ejecucion | AD14: Plataforma | AE14: NULL
A15: 640853827 | B15: ESEASA | C15: OGHACHI | E15: 13 | F15: 217 | G15: S/N | H15: 74 | I15: 19 | J15: 1 | K15: EMTR-4 OGHACHI | L15: 2024 | M15: 0 | N15: 0 | O15: EMTR-4 OGHACHI | P15: 1 | Q15: NO | R15: NO | S15: NO | T15: NO | U15: NULL | V15: NULL | W15: NULL | X15: 45090 | Y15: 45471 | AA15: 45561 | AB15: Marina | AC15: Ejecucion | AD15: Plataforma | AE15: NULL
A16: 640852811 | B16: SIGMA / SARREAL | C16: Ixachi | E16: 14 | F16: 308 | G16: OT-01 | H16: 64 | I16: 1 | J16: 1 | K16: GSD 24”Ø x 14.1 km de BS Ixachi a EMC Papán | L16: 2024 | M16: 0 | N16: 0 | O16: OT-01 Construcción de Gasoducto 24”Ø x 14.1 km de BS Ixachi a EMC Papán | P16: 1 | Q16: NO | R16: NO | S16: NO | T16: NO | U16: NULL | V16: NULL | W16: NULL | X16: 44698 | Y16: 44821 | Z16: 45107 | AA16: 45500 | AB16: Terrestre | AC16: Ejecucion | AD16: Ducto Terrestre | AE16: NULL
A17: 640852804 | B17: COCOMEX | C17: Jujo | E17: 15 | F17: 312 | G17: S/N | H17: 99 | I17: 23 | J17: 1 | K17: IPC Tecominoacán (Segunda Etapa) | L17: 2024 | M17: 0 | N17: 0 | O17: Ingeniería, procura, construcción y puesta en operación de obra electromecánica en la Bateria de Separación Tecominoacán (Segunda Etapa) | P17: 1 | Q17: NO | R17: NO | S17: NO | T17: NO | U17: NULL | V17: NULL | W17: NULL | X17: 44617 | Y17: 45066 | Z17: 45571 | AA17: 45620 | AB17: Terrestre | AC17: Ejecucion | AD17: OEM | AE17: NULL
A18: 640852811 | B18: SIGMA / SARREAL | C18: Ixachi | E18: 16 | F18: 330 | G18: OT-02 | H18: 64 | I18: 1 | J18: 1 | K18: OGD 20” Ø x 16 km TUM-1 a CPG Matapionche. | L18: 2024 | M18: 0 | N18: 0 | O18: OT-02 Oleogasoducto de 20” Ø x 16 km TUM-1 a CPG Matapionche. | P18: 1 | Q18: NO | R18: NO | S18: NO | T18: NO | U18: NULL | V18: NULL | W18: NULL | X18: 44739 | Y18: 45019 | Z18: 45329 | AA18: 45500 | AB18: Terrestre | AC18: Ejecucion | AD18: Ducto Terrestre | AE18: NULL
A19: 640852811 | B19: SIGMA / SARREAL | C19: Tupilco | E19: 17 | F19: 331 | G19: OT-03 | H19: 64 | I19: 15 | J19: 1 | K19: GSD 16"Ø x 13.2 km de Tupilco I - Los Sapos. | L19: 2024 | M19: 0 | N19: 0 | O19: OT-03 Gasoducto de 16"Ø x 13.2 km de Tupilco I - Los Sapos. | P19: 1 | Q19: NO | R19: NO | S19: NO | T19: NO | U19: NULL | V19: NULL | W19: NULL | X19: 44819 | Y19: 44940 | Z19: 45071 | AA19: 45500 | AB19: Terrestre | AC19: Ejecucion | AD19: Ducto Terrestre | AE19: NULL
A20: 640852821 | B20: AEME | C20: N/A | E20: 18 | F20: 333 | G20: S/N | H20: 55 | I20: 24 | J20: 1 | K20: Sistema de Endulzamiento y Compresion de Gas en TMDB | L20: 2024 | M20: 0 | N20: 0 | O20: Sistema de Endulzamiento y Compresion de Gas en TMDB | P20: 1 | Q20: NO | R20: NO | S20: NO | T20: NO | U20: NULL | V20: NULL | W20: NULL | X20: 44813 | Y20: 45412 | Z20: 45690 | AA20: 45690 | AB20: Marina | AC20: Ejecucion | AD20: OEM | AE20: NULL
A21: 640852822 | B21: TURBOMAQUINARIA | C21: Rabasa | E21: 19 | F21: 334 | G21: S/N | H21: 69 | I21: 25 | J21: 1 | K21: BS Rabasa, Segunda Etapa | L21: 2024 | M21: 0 | N21: 0 | O21: Batería de Separación Rabasa, Segunda Etapa | P21: 1 | Q21: NO | R21: NO | S21: NO | T21: NO | U21: NULL | V21: NULL | W21: NULL | X21: 44812 | Y21: 45261 | Z21: 45531 | AA21: 45561 | AB21: Terrestre | AC21: Ejecucion | AD21: OEM | AE21: NULL
A22: 640851807 | B22: NUVOIL | C22: Ixachi | E22: 20 | F22: 335 | G22: S/N | H22: 60 | I22: 1 | J22: 1 | K22: Servicio Integral de Acondicionamiento de Gas Húmedo Amargo del Campo Ixachi EMC Papan | L22: 2024 | M22: 0 | N22: 0 | O22: Servicio Integral de Acondicionamiento de Gas Húmedo Amargo del Campo Ixachi EMC Papan | P22: 1 | Q22: NO | R22: NO | S22: NO | T22: NO | U22: NULL | V22: NULL | W22: NULL | X22: 44554 | Y22: 44743 | Z22: 45430 | AA22: 45562 | AB22: Terrestre | AC22: Ejecucion | AD22: OEM | AE22: NULL
A23: 640852824 | B23: DIAVAZ | C23: Teca | E23: 21 | F23: 364 | G23: S/N | H23: 56 | I23: 26 | J23: 1 | K23: OEM en las Plataformas Marinas Teca-A para inyección de agua de mar a pozos. | L23: 2024 | M23: 0 | N23: 0 | O23: OEM en las Plataformas Marinas Teca-A para inyección de agua de mar a pozos. | P23: 1 | Q23: NO | R23: NO | S23: NO | T23: NO | U23: NULL | V23: NULL | W23: NULL | X23: 44865 | Y23: 45082 | Z23: 45511 | AA23: 45550 | AB23: Marina | AC23: Ejecucion | AD23: OEM | AE23: NULL
A24: 640852824 | B24: DIAVAZ | C24: Tlacame | E24: 22 | F24: 365 | G24: S/N | H24: 56 | I24: 14 | J24: 1 | K24: OEM en las Plataformas Marinas Tlacame-A para inyección de agua de mar a pozos. | L24: 2024 | M24: 0 | N24: 0 | O24: OEM en las Plataformas Marinas Tlacame-A para inyección de agua de mar a pozos. | P24: 1 | Q24: NO | R24: NO | S24: NO | T24: NO | U24: NULL | V24: NULL | W24: NULL | X24: 44865 | Y24: 45163 | Z24: 45525 | AA24: 45555 | AB24: Marina | AC24: Ejecucion | AD24: OEM | AE24: NULL
A25: 640852826 | B25: DEMAR | C25: Itta | E25: 23 | F25: 369 | G25: S/N | H25: 58 | I25: 27 | J25: 1 | K25: OEM en las Plataformas Marinas Itta-A para inyección de agua de mar a pozos. | L25: 2024 | M25: 0 | N25: 0 | O25: OEM en las Plataformas Marinas Itta-A para inyección de agua de mar a pozos. | P25: 1 | Q25: NO | R25: NO | S25: NO | T25: NO | U25: NULL | V25: NULL | W25: NULL | X25: 44865 | Y25: 45117 | AA25: 45519 | AB25: Marina | AC25: Ejecucion | AD25: OEM | AE25: NULL
A26: 640852826 | B26: DEMAR | C26: Teekit | E26: 24 | F26: 370 | G26: S/N | H26: 58 | I26: 28 | J26: 1 | K26: OEM en las Plataformas Marinas Teekit-A para inyección de agua de mar a pozos. | L26: 2024 | M26: 0 | N26: 0 | O26: OEM en las Plataformas Marinas Teekit-A para inyección de agua de mar a pozos. | P26: 1 | Q26: NO | R26: NO | S26: NO | T26: NO | U26: NULL | V26: NULL | W26: NULL | X26: 44865 | Y26: 45164 | Z26: 45259 | AA26: 45655 | AB26: Marina | AC26: Ejecucion | AD26: OEM | AE26: NULL
A27: 640852826 | B27: DEMAR | C27: Chahua | E27: 25 | F27: 371 | G27: S/N | H27: 58 | I27: 29 | J27: 1 | K27: OEM en las Plataformas Marinas Cahua-A para inyección de agua de mar a pozos. | L27: 2024 | M27: 0 | N27: 0 | O27: OEM en las Plataformas Marinas Cahua-A para inyección de agua de mar a pozos. | P27: 1 | Q27: NO | R27: NO | S27: NO | T27: NO | U27: NULL | V27: NULL | W27: NULL | X27: 45193 | Y27: 45519 | Z27: 45742 | AA27: 45772 | AB27: Marina | AC27: Ejecucion | AD27: OEM | AE27: NULL
A28: 640852811 | B28: SIGMA / SARREAL | C28: Ixachi | E28: 26 | F28: 377 | G28: OT-04 | H28: 64 | I28: 1 | J28: 1 | K28: OGD 24” x 5.5 km de MP Ixachi 1DEL a B.S. Perdiz. | L28: 2024 | M28: 0 | N28: 0 | O28: OT-04 Oleogasoducto de 24” x 5.5 km de MP Ixachi 1DEL a B.S. Perdiz. | P28: 1 | Q28: NO | R28: NO | S28: NO | T28: NO | U28: NULL | V28: NULL | W28: NULL | X28: 44874 | Y28: 45081 | Z28: 45501 | AA28: 45503 | AB28: Terrestre | AC28: Ejecucion | AD28: Ducto Terrestre | AE28: NULL
A29: 640852828 | B29: ÁGUILA | C29: Ixachi | E29: 27 | F29: 391 | G29: OT-01 | H29: 70 | I29: 1 | J29: 1 | K29: Paquete de Medicion IXACHI Pozo Mocarroca 1 | L29: 2024 | M29: 0 | N29: 0 | O29: OT-01 Paquete de Medición Compacto No. 1, Campo Ixachi, Pozo Mocarroca 1 | P29: 1 | Q29: NO | R29: NO | S29: NO | T29: NO | U29: NULL | V29: NULL | W29: NULL | X29: 44970 | Y29: 45179 | Z29: 45552 | AA29: 45552 | AB29: Terrestre | AC29: Ejecucion | AD29: OEM | AE29: NULL
A30: 640852831 | B30: DEMAR | C30: Utsil | E30: 28 | F30: 398 | G30: S/N | H30: 59 | I30: 30 | J30: 1 | K30: Cables Eléctricos Submarinos. Circuito Ayatsil-C hacia UTSIL-A | L30: 2024 | M30: 0 | N30: 0 | O30: Cables Eléctricos Submarinos. Circuito Ayatsil-C hacia UTSIL-A | P30: 1 | Q30: NO | R30: NO | S30: NO | T30: NO | U30: NULL | V30: NULL | W30: NULL | X30: 44918 | Y30: 45352 | Z30: 45716 | AA30: 45731 | AB30: Marina | AC30: Ejecucion | AD30: Cables Submarinos | AE30: NULL
A31: 640852831 | B31: DEMAR | C31: Yaxché | E31: 29 | F31: 399 | G31: S/N | H31: 59 | I31: 18 | J31: 1 | K31: Cables Eléctricos Submarinos. Circuito CB-LIT-A hacia YAXCHE-AI | L31: 2024 | M31: 0 | N31: 0 | O31: Cables Eléctricos Submarinos. Circuito CB-LIT-A hacia YAXCHE-AI | P31: 1 | Q31: NO | R31: NO | S31: NO | T31: NO | U31: NULL | V31: NULL | W31: NULL | X31: 44918 | Y31: 45472 | Z31: 45615 | AA31: 45660 | AB31: Marina | AC31: Ejecucion | AD31: Cables Submarinos | AE31: NULL
A32: 640852834 | B32: U.S.A. TECHNOLOGIES | C32: Perdiz | E32: 30 | F32: 400 | G32: S/N | H32: 61 | I32: 31 | J32: 1 | K32: Construcción de un Tanque de almacenamiento y obras comp. en la BS Perdiz. | L32: 2024 | M32: 0 | N32: 0 | O32: Procura, Construcción, Prueba y Puesta en Operación de un Tanque de almacenamiento y obras complementarias en la Batería de Separación Perdiz. | P32: 1 | Q32: NO | R32: NO | S32: NO | T32: NO | U32: NULL | V32: NULL | W32: NULL | X32: 44936 | Y32: 45145 | Z32: 45457 | AA32: 45467 | AB32: Terrestre | AC32: Ejecucion | AD32: OEM | AE32: NULL
A33: 640853808 | B33: AEME | C33: Jujo | E33: 31 | F33: 407 | G33: S/N | H33: 101 | I33: 23 | J33: 1 | K33: IPC y Puesta en Operación de OEM en la BS Jujo (Segunda Etapa) | L33: 2024 | M33: 0 | N33: 0 | O33: Ingeniería, Procura, Construcción y Puesta en Operación de Obra Electromecánica en la Batería de Separación Jujo (Segunda Etapa) | P33: 1 | Q33: NO | R33: NO | S33: NO | T33: NO | U33: NULL | V33: NULL | W33: NULL | X33: 44970 | Y33: 45485 | Z33: 45771 | AA33: 45842 | AB33: Terrestre | AC33: Ejecucion | AD33: OEM | AE33: NULL
A34: 640852811 | B34: SIGMA / SARREAL | C34: Quesqui | E34: 32 | F34: 408 | G34: OT-05 | H34: 64 | I34: 11 | J34: 1 | K34: OGD 30"Ø x 5.2 km MP Quesqui-41 a B.S. Jujo | L34: 2024 | M34: 0 | N34: 0 | O34: OT-05 Oleogasoducto de 30"Ø x 5.2 km MP Quesqui-41 a Batería de separación Jujo (Tramo del Km. 16 +200 al Km. 21 +400)”. | P34: 1 | Q34: NO | R34: NO | S34: NO | T34: NO | U34: NULL | V34: NULL | W34: NULL | X34: 44972 | Y34: 45041 | Z34: 45069 | AA34: 45500 | AB34: Terrestre | AC34: Ejecucion | AD34: Ducto Terrestre | AE34: NULL
A35: 640852828 | B35: ÁGUILA | C35: Ixachi | E35: 33 | F35: 409 | G35: OT-02 | H35: 70 | I35: 1 | J35: 1 | K35: Paquete de Medicion IXACHI Pozo Ixachi 30 | L35: 2024 | M35: 0 | N35: 0 | O35: OT-02 Paquete de Medición Compacto No. 2, Campo Ixachi, Pozo Ixachi 30 | P35: 1 | Q35: NO | R35: NO | S35: NO | T35: NO | U35: NULL | V35: NULL | W35: NULL | X35: 44970 | Y35: 45179 | Z35: 45565 | AA35: 45565 | AB35: Terrestre | AC35: Ejecucion | AD35: OEM | AE35: NULL
A36: 640852828 | B36: ÁGUILA | C36: Ixachi | E36: 34 | F36: 410 | G36: OT-03 | H36: 70 | I36: 1 | J36: 1 | K36: Paquete de Medicion IXACHI Batería Perdiz/Ixachi | L36: 2024 | M36: 0 | N36: 0 | O36: OT-03 Paquete de Medición Compacto No. 3, Campo Ixachi, Batería Perdiz/Ixachi | P36: 1 | Q36: NO | R36: NO | S36: NO | T36: NO | U36: NULL | V36: NULL | W36: NULL | X36: 44970 | Y36: 45179 | Z36: 45565 | AA36: 45565 | AB36: Terrestre | AC36: Ejecucion | AD36: OEM | AE36: NULL
A37: 640852828 | B37: ÁGUILA | C37: Quesqui | E37: 35 | F37: 411 | G37: OT-04 | H37: 70 | I37: 11 | J37: 1 | K37: Paquete de Medicion Quesqui, BS Tecominoacán | L37: 2024 | M37: 0 | N37: 0 | O37: OT-04 Paquete de Medición Compacto No. 4, Campo Quesqui, BS Tecominoacán | P37: 1 | Q37: NO | R37: NO | S37: NO | T37: NO | U37: NULL | V37: NULL | W37: NULL | X37: 44970 | Y37: 45179 | Z37: 45565 | AA37: 45565 | AB37: Terrestre | AC37: Ejecucion | AD37: OEM | AE37: NULL
... A53: 640853823 | B53: ESEASA | C53: Ixachi | E53: 51 | F53: 462 | G53: S/N | H53: 85 | I53: 1 | J53: 1 | K53: GSD de 20"Ø x 52 km de BS Ixachi / Perdiz a C.P.G. Matapionche (Seccion 2) | L53: 2024 | M53: 0 | N53: 0 | O53: Ingeniería, Procura, Fabricación, Construcción, Instalación, Interconexión, Pruebas y Puesta en operación del Gasoducto de 20” x 52 km de Batería de Separación Ixachi / Perdiz a C.P.G. Matapionche (Sección 2, de M.P. Huace a B.S Matapionche). | P53: 1 | Q53: NO | R53: NO | S53: NO | T53: NO | U53: NULL | V53: NULL | W53: NULL | X53: 45037 | Y53: 45246 | Z53: 45534 | AA53: 45586 | AB53: Terrestre | AC53: Ejecucion | AD53: Ducto Terrestre | AE53: NULL
A54: 640852812 | B54: TERMOTECNICA | C54: Cibix | E54: 52 | F54: 463 | G54: OT-07 | H54: 65 | I54: 33 | J54: 1 | K54: OGD de 16" Ø de la MP Cibix 31 a Int. OGD Cibix-32 | L54: 2024 | M54: 0 | N54: 0 | O54: OT-07 OGD de 16” Ø de la MP Cibix 31 a Int. Oleogasoducto Cibix-32 | P54: 1 | Q54: NO | R54: NO | S54: NO | T54: NO | U54: NULL | V54: NULL | W54: NULL | X54: 45019 | Y54: 45100 | AB54: Terrestre | AC54: Ejecucion | AD54: Ducto Terrestre | AE54: NULL
A55: 640852812 | B55: TERMOTECNICA | C55: Cibix | E55: 53 | F55: 467 | G55: OT-08 | H55: 65 | I55: 33 | J55: 1 | K55: OGD de 12" x 5.73 km del Pozo Cibix 401 al Cabezal de Recolección Cibix 1 | L55: 2024 | M55: 0 | N55: 0 | O55: OT-08 OGD de 12” x 5.73 km del Pozo Cibix 401 al Cabezal de Recolección Cibix 1 | P55: 1 | Q55: NO | R55: NO | S55: NO | T55: NO | U55: NULL | V55: NULL | W55: NULL | X55: 45048 | Y55: 45268 | Z55: 45304 | AA55: 45412 | AB55: Terrestre | AC55: Ejecucion | AD55: Ducto Terrestre | AE55: NULL
A56: 640852812 | B56: TERMOTECNICA | C56: Platao | E56: 54 | F56: 468 | G56: OT-09 | H56: 65 | I56: 36 | J56: 1 | K56: OGD de 8" Ø x 2.1 km de la MP Platao-1EXP a Interconexión con OGD 16"Ø de TMDB a B.S. Cunduacan (1era. Etapa) | L56: 2024 | M56: 0 | N56: 0 | O56: OT-09 OGD de 8” Ø x 2.1 km de la MP Platao-1EXP a Interconexión con OGD 16”Ø de TMDB a B.S. Cunduacan (1era. Etapa) | P56: 1 | Q56: NO | R56: NO | S56: NO | T56: NO | U56: NULL | V56: NULL | W56: NULL | X56: 45048 | Y56: 45192 | Z56: 45332 | AA56: 45412 | AB56: Terrestre | AC56: Ejecucion | AD56: Ducto Terrestre | AE56: NULL
...

Sheet Hoja7
B2: Cantarel | C2: =VLOOKUP(B2,Hoja8!$A$3:$D$21,2,FALSE) -> #N/A
B3: Yaxché | C3: =VLOOKUP(B3,Hoja8!$A$3:$D$21,2,FALSE) -> 18
B4: Tlacame | C4: =VLOOKUP(B4,Hoja8!$A$3:$D$21,2,FALSE) -> 14
B5: Tlacame | C5: =VLOOKUP(B5,Hoja8!$A$3:$D$21,2,FALSE) -> 14
B6: Tlacame | C6: =VLOOKUP(B6,Hoja8!$A$3:$D$21,2,FALSE) -> 14
B7: Xanab | C7: =VLOOKUP(B7,Hoja8!$A$3:$D$21,2,FALSE) -> 17
B8: Yaxché | C8: =VLOOKUP(B8,Hoja8!$A$3:$D$21,2,FALSE) -> 18
B9: Pokche | C9: =VLOOKUP(B9,Hoja8!$A$3:$D$21,2,FALSE) -> #N/A
B10: Tentok | C10: =VLOOKUP(B10,Hoja8!$A$3:$D$21,2,FALSE) -> #N/A
B11: MACUIL | C11: =VLOOKUP(B11,Hoja8!$A$3:$D$21,2,FALSE) -> 10
B12: MACUIL | C12: =VLOOKUP(B12,Hoja8!$A$3:$D$21,2,FALSE) -> 10
B13: ATOYATL | C13: =VLOOKUP(B13,Hoja8!$A$3:$D$21,2,FALSE) -> 6
... B109: Techiaktli | C109: =VLOOKUP(B109,Hoja8!$A$3:$D$21,2,FALSE) -> 12

Sheet Hoja8
B2: id | C2: id_contract | D2: name
A3: IXACHI | B3: 1 | C3: 1 | D3: IXACHI
A4: PLATAU | B4: 2 | C4: 1 | D4: PLATAU
A5: ACTUL | B5: 3 | C5: 1 | D5: ACTUL
A6: IKLUM | B6: 4 | C6: 2 | D6: IKLUM
A7: SIN CAMPO | B7: 5 | C7: 3 | D7: SIN CAMPO
A8: ATOYATL | B8: 6 | C8: 1 | D8: ATOYATL
A9: KASEN | B9: 7 | C9: 1 | D9: KASEN
A10: KUIL | B10: 8 | C10: 1 | D10: KUIL
A11: LOS SOLDADOS | B11: 9 | C11: 1 | D11: LOS SOLDADOS
A12: MACUIL | B12: 10 | C12: 1 | D12: MACUIL
A13: QUESQUI | B13: 11 | C13: 1 | D13: QUESQUI
A14: TECHIAKTLI | B14: 12 | C14: 1 | D14: TECHIAKTLI
... A21: OGHACHI | B21: 19 | C21: 1 | D21: OGHACHI

Sheet Hoja2
C2: name | D2: corto
B3: S/N | C3: Ingeniería, Procura, Construcción de un Gasoducto de 8”Ø x 8.2 km de PP-Akal-B-1 hacia PP-Ek-A; By Pass submarino de 20”Ø x 0.2 km. | D3: =VLOOKUP(C3,Hoja3!$B$3:$C$373,2,FALSE) -> IPC en GSD 8" Ø X 8.2 km de PP-Akal-B-1 | E3: =VLOOKUP(C3,Hoja3!$B$3:$D$373,3,FALSE) -> Cantarel
B4: S/N | C4: GSD de BN 16”Ø x 20 Km Yaxché-A hacia Tlacame-A | D4: =VLOOKUP(C4,Hoja3!$B$3:$C$373,2,FALSE) -> GSD de BN 16”Ø x 20 Km Yaxché-A hacia Tlacame-A | E4: =VLOOKUP(C4,Hoja3!$B$3:$D$373,3,FALSE) -> Yaxché
B5: S/N | C5: OGD de 20”Ø x 8.8 Km Mulach-A hacia Interc. Subm. con OGD Tlacame-A / Xanab-C | D5: =VLOOKUP(C5,Hoja3!$B$3:$C$373,2,FALSE) -> OGD de 20”Ø x 8.8 Km Mulach-A hacia Interc. Subm. con OGD Tlacame-A / Xanab-C | E5: =VLOOKUP(C5,Hoja3!$B$3:$D$373,3,FALSE) -> Tlacame
B6: S/N | C6: GSD de BN 16”Ø x 0.5 Km Interc. Subm. con OGD de 16” Tlacame-A hacia Mulach-A | D6: =VLOOKUP(C6,Hoja3!$B$3:$C$373,2,FALSE) -> GSD de BN 16”Ø x 0.5 Km Interc. Subm. con OGD de 16” Tlacame-A hacia Mulach-A | E6: =VLOOKUP(C6,Hoja3!$B$3:$D$373,3,FALSE) -> Tlacame
B7: S/N | C7: OGD de 16”Ø x 6.8 Km de la plataforma Xanab-201 hacia la plataforma Xanab-D | D7: =VLOOKUP(C7,Hoja3!$B$3:$C$373,2,FALSE) -> OGD de 16”Ø x 6.8 Km de la plataforma Xanab-201 hacia la plataforma Xanab-D | E7: =VLOOKUP(C7,Hoja3!$B$3:$D$373,3,FALSE) -> Tlacame
B8: S/N | C8: Plataforma Recuperadora de Pozos tipo Típode Xanab-201 | D8: =VLOOKUP(C8,Hoja3!$B$3:$C$373,2,FALSE) -> Plataforma Recuperadora de Pozos tipo Típode Xanab-201 | E8: =VLOOKUP(C8,Hoja3!$B$3:$D$373,3,FALSE) -> Xanab
B9: S/N | C9: Plataforma de Inyección de Agua de Mar Yaxche-AI | D9: =VLOOKUP(C9,Hoja3!$B$3:$C$373,2,FALSE) -> Plataforma de Inyección de Agua de Mar Yaxche-AI | E9: =VLOOKUP(C9,Hoja3!$B$3:$D$373,3,FALSE) -> Yaxché
B10: S/N | C10: EMDR-1-POKCHE-NE | D10: =VLOOKUP(C10,Hoja3!$B$3:$C$373,2,FALSE) -> EMDR-1-POKCHE-NE | E10: =VLOOKUP(C10,Hoja3!$B$3:$D$373,3,FALSE) -> Pokche
B11: S/N | C11: EMDR-2 TENTOK | D11: =VLOOKUP(C11,Hoja3!$B$3:$C$373,2,FALSE) -> EMDR-2 TENTOK | E11: =VLOOKUP(C11,Hoja3!$B$3:$D$373,3,FALSE) -> Tentok
B12: S/N | C12: EMTR-1 ( EX TENTOK) | D12: =VLOOKUP(C12,Hoja3!$B$3:$C$373,2,FALSE) -> EMTR-1 ( EX TENTOK) | E12: =VLOOKUP(C12,Hoja3!$B$3:$D$373,3,FALSE) -> MACUIL
B13: S/N | C13: EMTR-2 MACUIL | D13: =VLOOKUP(C13,Hoja3!$B$3:$C$373,2,FALSE) -> EMTR-2 MACUIL | E13: =VLOOKUP(C13,Hoja3!$B$3:$D$373,3,FALSE) -> MACUIL
B14: S/N | C14: EMTR-3 ATOYATL | D14: =VLOOKUP(C14,Hoja3!$B$3:$C$373,2,FALSE) -> EMTR-3 ATOYATL | E14: =VLOOKUP(C14,Hoja3!$B$3:$D$373,3,FALSE) -> ATOYATL
... B36: OT-03 | C36: Paquete de Medición Compacto No. 3, Campo Ixachi, Batería Perdiz/Ixachi | D36: =VLOOKUP(C36,Hoja3!$B$3:$C$373,2,FALSE) -> Paquete de Medicion IXACHI Batería Perdiz/Ixachi | E36: =VLOOKUP(C36,Hoja3!$B$3:$D$373,3,FALSE) -> Ixachi
B37: OT-04 | C37: Paquete de Medición Compacto No. 4, Campo Quesqui, BS Tecominoacán | D37: =VLOOKUP(C37,Hoja3!$B$3:$C$373,2,FALSE) -> Paquete de Medicion Quesqui, BS Tecominoacán | E37: =VLOOKUP(C37,Hoja3!$B$3:$D$373,3,FALSE) -> Quesqui | L37: =LEFT(C37,6) -> Paquet
B38: OT-05 | C38: Paquete de Medición Compacto No. 5, Campo Tupilco, BS Tupilco | D38: =VLOOKUP(C38,Hoja3!$B$3:$C$373,2,FALSE) -> Paquete de Medicion Tupilco, BS Tupilco | E38: =VLOOKUP(C38,Hoja3!$B$3:$D$373,3,FALSE) -> Tupilco | L38: =LEFT(C38,6) -> Paquet
B39: OT-06 | C39: Paquete de Medición Compacto No. 6, Campo Valeriana, Pozo Valeriana 1 | D39: =VLOOKUP(C39,Hoja3!$B$3:$C$373,2,FALSE) -> Paquete de Medicion Valeriana, Pozo Valeriana 1 | E39: =VLOOKUP(C39,Hoja3!$B$3:$D$373,3,FALSE) -> Valeriana | L39: =LEFT(C39,6) -> Paquet
B40: OT-07 | C40: Paquete de Medición Compacto No. 7, Campo Ixachi, Pozo Perdiz 579 | D40: =VLOOKUP(C40,Hoja3!$B$3:$C$373,2,FALSE) -> Paquete de Medicion Ixachi, Pozo Perdiz 579 | E40: =VLOOKUP(C40,Hoja3!$B$3:$D$373,3,FALSE) -> Ixachi | L40: =LEFT(C40,6) -> Paquet
B41: OT-08 | C41: Paquete de Medición Compacto No. 8, Campo Ixachi, Pozo Ixachi 1DEL | D41: =VLOOKUP(C41,Hoja3!$B$3:$C$373,2,FALSE) -> Paquete de Medicion Ixachi, Pozo Ixachi 1DEL | E41: =VLOOKUP(C41,Hoja3!$B$3:$D$373,3,FALSE) -> Ixachi | L41: =LEFT(C41,6) -> Paquet
B42: OT-09 | C42: Paquete de Medición Compacto No. 9, Campo Ixachi, Pozo Ixachi 34 | D42: =VLOOKUP(C42,Hoja3!$B$3:$C$373,2,FALSE) -> Paquete de Medicion Ixachi, Pozo Ixachi 34 | E42: =VLOOKUP(C42,Hoja3!$B$3:$D$373,3,FALSE) -> Ixachi | L42: =LEFT(C42,6) -> Paquet
B43: OT-10 | C43: Paquete de Medición Compacto No. 10, Campo Quesqui, Pozo Quesqui 4DEL | D43: =VLOOKUP(C43,Hoja3!$B$3:$C$373,2,FALSE) -> Paquete de Medicion Quesqui, Pozo Quesqui 4DEL | E43: =VLOOKUP(C43,Hoja3!$B$3:$D$373,3,FALSE) -> Quesqui | L43: =LEFT(C43,6) -> Paquet
B44: OT-11 | C44: Paquete de Medición Compacto No. 11, Campo Ixachi, Pozo Ixachi 2001 | D44: =VLOOKUP(C44,Hoja3!$B$3:$C$373,2,FALSE) -> Paquete de Medicion Ixachi, Pozo Ixachi 2001 | E44: =VLOOKUP(C44,Hoja3!$B$3:$D$373,3,FALSE) -> Ixachi | L44: =LEFT(C44,6) -> Paquet
B45: OT-12 | C45: Paquete de Medición Compacto No. 12, Campo Ixachi, Pozo Perdiz 509 | D45: =VLOOKUP(C45,Hoja3!$B$3:$C$373,2,FALSE) -> Paquete de Medicion Ixachi, Pozo Perdiz 509 | E45: =VLOOKUP(C45,Hoja3!$B$3:$D$373,3,FALSE) -> Ixachi | L45: =LEFT(C45,6) -> Paquet
B46: OT-13 | C46: Paquete de Medición Compacto No. 13, Campo Ixachi, Pozo Ixachi 44 | D46: =VLOOKUP(C46,Hoja3!$B$3:$C$373,2,FALSE) -> Paquete de Medicion Ixachi, Pozo Ixachi 44 | E46: =VLOOKUP(C46,Hoja3!$B$3:$D$373,3,FALSE) -> Ixachi | L46: =LEFT(C46,6) -> Paquet
B47: OT-14 | C47: Paquete de Medición Compacto No. 14, Campo Ixachi, Pozo Ixachi 12 | D47: =VLOOKUP(C47,Hoja3!$B$3:$C$373,2,FALSE) -> Paquete de Medicion Ixachi, Pozo Ixachi 12 | E47: =VLOOKUP(C47,Hoja3!$B$3:$D$373,3,FALSE) -> Ixachi | L47: =LEFT(C47,6) -> Paquet
B48: OT-15 | C48: Paquete de Medición Compacto No. 15, Campo Ixachi, Pozo Perdiz 39 | D48: =VLOOKUP(C48,Hoja3!$B$3:$C$373,2,FALSE) -> Paquete de Medicion Ixachi, Pozo Perdiz 39 | E48: =VLOOKUP(C48,Hoja3!$B$3:$D$373,3,FALSE) -> Ixachi | L48: =LEFT(C48,6) -> Paquet
... B51: OT-06 | C51: OGD de 8"Ø x 5.738.098 km del Pozo Cibix-401 al cabezal de recolección Cibix-1 | D51: =VLOOKUP(C51,Hoja3!$B$3:$C$373,2,FALSE) -> OGD de 8"Ø x 5.738.098 km del Pozo Cibix-401 | E51: =VLOOKUP(C51,Hoja3!$B$3:$D$373,3,FALSE) -> Cibix | L51: =LEFT(C51,6) -> OGD de
B52: S/N | C52: 1 | D52: =VLOOKUP(C52,Hoja3!$B$3:$C$373,2,FALSE) -> GSD de 20"Ø x 52 km de BS Ixachi / Perdiz a C.P.G. Matapionche (Seccion 3) | E52: =VLOOKUP(C52,Hoja3!$B$3:$D$373,3,FALSE) -> Ixachi | L52: =LEFT(C52,6) -> 1
B53: S/N | C53: Ingeniería, Procura, Fabricación, Construcción, Instalación, Interconexión, Pruebas y Puesta en operación del Gasoducto de 20” x 52 km de Batería de Separación Ixachi / Perdiz a C.P.G. Matapionche (Sección 2, de M.P. Huace a B.S Matapionche). | D53: =VLOOKUP(C53,Hoja3!$B$3:$C$373,2,FALSE) -> GSD de 20"Ø x 52 km de BS Ixachi / Perdiz a C.P.G. Matapionche (Seccion 2) | E53: =VLOOKUP(C53,Hoja3!$B$3:$D$373,3,FALSE) -> Ixachi | L53: =LEFT(C53,6) -> Ingeni
B54: OT-07 | C54: OGD de 16” Ø de la MP Cibix 31 a Int. Oleogasoducto Cibix-32 | D54: =VLOOKUP(C54,Hoja3!$B$3:$C$373,2,FALSE) -> OGD de 16" Ø de la MP Cibix 31 a Int. OGD Cibix-32 | E54: =VLOOKUP(C54,Hoja3!$B$3:$D$373,3,FALSE) -> Cibix | L54: =LEFT(C54,6) -> OGD de
B55: OT-08 | C55: OGD de 12” x 5.73 km del Pozo Cibix 401 al Cabezal de Recolección Cibix 1 | D55: =VLOOKUP(C55,Hoja3!$B$3:$C$373,2,FALSE) -> OGD de 12" x 5.73 km del Pozo Cibix 401 al Cabezal de Recolección Cibix 1 | E55: =VLOOKUP(C55,Hoja3!$B$3:$D$373,3,FALSE) -> Cibix | L55: =LEFT(C55,6) -> OGD de
B56: OT-09 | C56: OGD de 8” Ø x 2.1 km de la MP Platao-1EXP a Interconexión con OGD 16”Ø de TMDB a B.S. Cunduacan (1era. Etapa) | D56: =VLOOKUP(C56,Hoja3!$B$3:$C$373,2,FALSE) -> OGD de 8" Ø x 2.1 km de la MP Platao-1EXP a Interconexión con OGD 16"Ø de TMDB a B.S. Cunduacan (1era. Etapa) | E56: =VLOOKUP(C56,Hoja3!$B$3:$D$373,3,FALSE) -> Platao | L56: =LEFT(C56,6) -> OGD de
B57: OT-06 | C57: Oleogasoducto de 30"Ø x 1.6 km de la MP Ixachi-30 a la MP Ixachi 34 (primera etapa) | D57: =VLOOKUP(C57,Hoja3!$B$3:$C$373,2,FALSE) -> OGD 30"Ø x 1.6 km de MP Ixachi-30 a la MP Ixachi 34 (primera etapa) | E57: =VLOOKUP(C57,Hoja3!$B$3:$D$373,3,FALSE) -> Ixachi | L57: =LEFT(C57,6) -> Oleoga
B58: S/N | C58: Servicio Integral de Inyección de Agua para Campos Estratégicos | D58: =VLOOKUP(C58,Hoja3!$B$3:$C$373,2,FALSE) -> Servicio Integral de Inyección de Agua para Campos Estratégicos | E58: =VLOOKUP(C58,Hoja3!$B$3:$D$373,3,FALSE) -> N/A | L58: =LEFT(C58,6) -> Servic
B59: S/N | C59: Construcción de camino de acceso, Localización de perforación y presa de quema para el pozo exploratorio NICHTE 1 | D59: =VLOOKUP(C59,Hoja3!$B$3:$C$373,2,FALSE) -> #N/A | E59: =VLOOKUP(C59,Hoja3!$B$3:$D$373,3,FALSE) -> #N/A | L59: =LEFT(C59,6) -> Constr
B60: OT-07 | C60: OGD de 30” x 22 km MP Cibix-1 a BS Oxiacaque (Tramo 2, km 7+333 – 14+666) | D60: =VLOOKUP(C60,Hoja3!$B$3:$C$373,2,FALSE) -> OGD 30” x 22 km MP Cibix-1 a BS Oxiacaque (Tramo 2) | E60: =VLOOKUP(C60,Hoja3!$B$3:$D$373,3,FALSE) -> Cibix | L60: =LEFT(C60,6) -> OGD de
B61: OT-11 | C61: Construcción de oleogasoducto de 30” ø x 22 kms. de la macropera cibix 1 a batería de separación oxiacaque (tramo 1 del km. 0+000 al km. 7+333 aproximadamente) | D61: =VLOOKUP(C61,Hoja3!$B$3:$C$373,2,FALSE) -> OGD de 30" x 22 kms. de la MP cibix 1 a BS oxiacaque (tramo 1) | E61: =VLOOKUP(C61,Hoja3!$B$3:$D$373,3,FALSE) -> Cibix | L61: =LEFT(C61,6) -> Constr
B62: S/N | C62: Construcción de la Plataforma de Perforación tipo Estructura Ligera Marina Genérica, Prospecto P-8 AKAL-NW | D62: =VLOOKUP(C62,Hoja3!$B$3:$C$373,2,FALSE) -> Construcción de la Plataforma de Perforación tipo ELMG, Prospecto P-8 AKAL-NW | E62: =VLOOKUP(C62,Hoja3!$B$3:$D$373,3,FALSE) -> Cantarel | L62: =LEFT(C62,6) -> Constr
B63: S/N | C63: Construcción de las Plataformas de Perforación tipo Estructura Ligera Marina Genéricas, Prospecto P-1. | D63: =VLOOKUP(C63,Hoja3!$B$3:$C$373,2,FALSE) -> Construcción de las Plataformas de Perforación tipo ELMG, Prospecto P-1. | E63: =VLOOKUP(C63,Hoja3!$B$3:$D$373,3,FALSE) -> Cantarel | L63: =LEFT(C63,6) -> Constr
B64: S/N | C64: Construcción de las Plataformas de Perforación tipo Estructura Ligera Marina Genéricas, Prospecto P-2. | D64: =VLOOKUP(C64,Hoja3!$B$3:$C$373,2,FALSE) -> Construcción de las Plataformas de Perforación tipo ELMG, Prospecto P-2. | E64: =VLOOKUP(C64,Hoja3!$B$3:$D$373,3,FALSE) -> Cantarel | L64: =LEFT(C64,6) -> Constr
...

Sheet Hoja3
B2: description | C2: name
B3: GSD de BN 16”Ø x 20 Km Yaxché-A hacia Tlacame-A | C3: GSD de BN 16”Ø x 20 Km Yaxché-A hacia Tlacame-A | D3: Yaxché
B4: OGD de 20”Ø x 8.8 Km Mulach-A hacia Interc. Subm. con OGD Tlacame-A / Xanab-C | C4: OGD de 20”Ø x 8.8 Km Mulach-A hacia Interc. Subm. con OGD Tlacame-A / Xanab-C | D4: Tlacame
B5: GSD de BN 16”Ø x 0.5 Km Interc. Subm. con OGD de 16” Tlacame-A hacia Mulach-A | C5: GSD de BN 16”Ø x 0.5 Km Interc. Subm. con OGD de 16” Tlacame-A hacia Mulach-A | D5: Tlacame
B6: OGD de 16”Ø x 6.8 Km de la plataforma Xanab-201 hacia la plataforma Xanab-D | C6: OGD de 16”Ø x 6.8 Km de la plataforma Xanab-201 hacia la plataforma Xanab-D | D6: Tlacame
B7: Construcción de Gasoducto 24”Ø x 14.1 km de BS Ixachi a EMC Papán | C7: GSD 24”Ø x 14.1 km de BS Ixachi a EMC Papán | D7: Ixachi
B8: Oleogasoducto de 20” Ø x 16 km TUM-1 a CPG Matapionche. | C8: OGD 20” Ø x 16 km TUM-1 a CPG Matapionche. | D8: Ixachi
B9: Gasoducto de 16"Ø x 13.2 km de Tupilco I - Los Sapos. | C9: GSD 16"Ø x 13.2 km de Tupilco I - Los Sapos. | D9: Tupilco
B10: Oleogasoducto de 24” x 5.5 km de MP Ixachi 1DEL a B.S. Perdiz. | C10: OGD 24” x 5.5 km de MP Ixachi 1DEL a B.S. Perdiz. | D10: Ixachi
B11: Oleogasoducto de 30"Ø x 5.2 km MP Quesqui-41 a Batería de separación Jujo (Tramo del Km. 16 +200 al Km. 21 +400)”. | C11: OGD 30"Ø x 5.2 km MP Quesqui-41 a B.S. Jujo | D11: Quesqui
B12: Oleogasoducto de 30"Ø x 1.6 km de la MP Ixachi-30 a la MP Ixachi 34 (primera etapa) | C12: OGD 30"Ø x 1.6 km de MP Ixachi-30 a la MP Ixachi 34 (primera etapa) | D12: Ixachi
B13: OGD de 30” x 22 km MP Cibix-1 a BS Oxiacaque (Tramo 2, km 7+333 – 14+666) | C13: OGD 30” x 22 km MP Cibix-1 a BS Oxiacaque (Tramo 2) | D13: Cibix
B14: Construcción de Amarre definitivo de Pozos, incluye: Plataforma de Operación de Válvulas y Cerco Perimetral | C14: Amarre de Pozos definitivo en campo Ixachi | D14: Ixachi
... B64: OGD de 8"Ø x 5.738.098 km del Pozo Cibix-401 al cabezal de recolección Cibix-1 | C64: OGD de 8"Ø x 5.738.098 km del Pozo Cibix-401 | D64: Cibix
B65: 1 | C65: GSD de 20"Ø x 52 km de BS Ixachi / Perdiz a C.P.G. Matapionche (Seccion 3) | D65: Ixachi
B66: Ingeniería, Procura, Fabricación, Construcción, Instalación, Interconexión, Pruebas y Puesta en operación del Gasoducto de 20” x 52 km de Batería de Separación Ixachi / Perdiz a C.P.G. Matapionche (Sección 2, de M.P. Huace a B.S Matapionche). | C66: GSD de 20"Ø x 52 km de BS Ixachi / Perdiz a C.P.G. Matapionche (Seccion 2) | D66: Ixachi
B67: OGD de 16” Ø de la MP Cibix 31 a Int. Oleogasoducto Cibix-32 | C67: OGD de 16" Ø de la MP Cibix 31 a Int. OGD Cibix-32 | D67: Cibix
B68: OGD de 12” x 5.73 km del Pozo Cibix 401 al Cabezal de Recolección Cibix 1 | C68: OGD de 12" x 5.73 km del Pozo Cibix 401 al Cabezal de Recolección Cibix 1 | D68: Cibix
B69: OGD de 8” Ø x 2.1 km de la MP Platao-1EXP a Interconexión con OGD 16”Ø de TMDB a B.S. Cunduacan (1era. Etapa) | C69: OGD de 8" Ø x 2.1 km de la MP Platao-1EXP a Interconexión con OGD 16"Ø de TMDB a B.S. Cunduacan (1era. Etapa) | D69: Platao
B70: Servicio Integral de Inyección de Agua para Campos Estratégicos | C70: Servicio Integral de Inyección de Agua para Campos Estratégicos | D70: N/A
B71: Desarrollo de ingeniería, procura y construcción de un ducto de 8” ø x 13 km de Actul-1 hacia la B.S. Soldados. | C71: de IPC de un ducto de 8" x 13 km de Actul-1 hacia la B.S. Soldados. | D71: Actul
B72: Construcción de oleogasoducto de 30” ø x 22 kms. de la macropera cibix 1 a batería de separación oxiacaque (tramo 1 del km. 0+000 al km. 7+333 aproximadamente) | C72: OGD de 30" x 22 kms. de la MP cibix 1 a BS oxiacaque (tramo 1) | D72: Cibix
B73: Construcción de la Plataforma de Perforación tipo Estructura Ligera Marina Genérica, Prospecto P-8 AKAL-NW | C73: Construcción de la Plataforma de Perforación tipo ELMG, Prospecto P-8 AKAL-NW | D73: Cantarel
B74: Construcción de las Plataformas de Perforación tipo Estructura Ligera Marina Genéricas, Prospecto P-1. | C74: Construcción de las Plataformas de Perforación tipo ELMG, Prospecto P-1. | D74: Cantarel
B75: Construcción de las Plataformas de Perforación tipo Estructura Ligera Marina Genéricas, Prospecto P-2. | C75: Construcción de las Plataformas de Perforación tipo ELMG, Prospecto P-2. | D75: Cantarel
B76: Construcción de la Plataforma de Perforación tipo Estructura Ligera Marina Genérica, Prospecto P-7 | C76: Construcción de la Plataforma de Perforación tipo Estructura Ligera Marina Genérica, Prospecto P-7 | D76: Cantarel
B77: Oleogasoducto de 20” x 6.3 KM de EMDR Pokche-NE-A a Xanab-B | C77: OGD de 20" x 6.3 KM de EMDR Pokche-NE-A a Xanab-B | D77: Pokche
... B115: Habilitación de carril de desaceleración/aceleración, obras complementarias y señalética | C115: Hab. de carril de desaceleración/aceleración, obras comp. y señalética | D115: Chukox

Sheet Hoja6
B1: Contrato | C1: oilfield
B2: 640852805 | C2: ARENDAL | D2: =VLOOKUP(B2,Hoja5!$A$2:$E$95,2,FALSE) -> 78
B3: 640852806 | C3: DEMAR | D3: =VLOOKUP(B3,Hoja5!$A$2:$E$95,2,FALSE) -> 79
B4: 640852806 | C4: DEMAR | D4: =VLOOKUP(B4,Hoja5!$A$2:$E$95,2,FALSE) -> 79
B5: 640852806 | C5: DEMAR | D5: =VLOOKUP(B5,Hoja5!$A$2:$E$95,2,FALSE) -> 79
B6: 640852806 | C6: DEMAR | D6: =VLOOKUP(B6,Hoja5!$A$2:$E$95,2,FALSE) -> 79
B7: 640852818 | C7: PERMADUCTO | D7: =VLOOKUP(B7,Hoja5!$A$2:$E$95,2,FALSE) -> 72
B8: 640852818 | C8: PERMADUCTO | D8: =VLOOKUP(B8,Hoja5!$A$2:$E$95,2,FALSE) -> 72
B9: 640853826 | C9: ESEASA | D9: =VLOOKUP(B9,Hoja5!$A$2:$E$95,2,FALSE) -> 73
B10: 640853826 | C10: ESEASA | D10: =VLOOKUP(B10,Hoja5!$A$2:$E$95,2,FALSE) -> 73
B11: 640853827 | C11: ESEASA | D11: =VLOOKUP(B11,Hoja5!$A$2:$E$95,2,FALSE) -> 74
B12: 640853827 | C12: ESEASA | D12: =VLOOKUP(B12,Hoja5!$A$2:$E$95,2,FALSE) -> 74
B13: 640853827 | C13: ESEASA | D13: =VLOOKUP(B13,Hoja5!$A$2:$E$95,2,FALSE) -> 74
... B111: 640854812 | C111: MAYURSE | D111: =VLOOKUP(B111,Hoja5!$A$2:$E$95,2,FALSE) -> 144

Sheet Hoja5
B1: id | C1: Consecutive | D1: Speciality | E1: Contract
A2: 640835805 | B2: 30 | C2: 1 | D2: Patios | E2: 640835805
A3: 640837800 | B3: 31 | C3: 2 | D3: Patios | E3: 640837800
A4: 640851805 | B4: 32 | C4: 6 | D4: Instalaciones | E4: 640851805
A5: 640858818 | B5: 33 | C5: 11 | D5: Ductos Marinos | E5: 640858818
A6: 420832856 | B6: 34 | C6: 12 | D6: Ductos Marinos | E6: 420832856
A7: 420833820 | B7: 35 | C7: 13 | D7: Ductos Marinos | E7: 420833820
A8: 420832825 | B8: 36 | C8: 14 | D8: Terrestres | E8: 420832825
A9: 640858800 | B9: 37 | C9: 15 | D9: Ductos Marinos | E9: 640858800
A10: 640859815 | B10: 38 | C10: 19 | D10: Obras Marinas | E10: 640859815
A11: 640858803 | B11: 39 | C11: 20 | D11: Ductos Marinos | E11: 640858803
A12: 420832814 | B12: 40 | C12: 24 | D12: Patios | E12: 420832814
A13: 420832829 | B13: 41 | C13: 25 | D13: Instalaciones | E13: 420832829
... A95: 425022879 | B95: 147 | C95: 118 | D95: Terrestres | E95: 425022879
