Workbook

Sheet concentrado_mes
C2: INGRESO GENERAL
D3: Primer trimestre | G3: Segundo Trimestre | J3: Tercer Trimestre | M3: Cuarto Trimestre
B4: A | C4: CONCEPTO/MES | D4: OCT-24 | E4: NOV-24 | F4: DIC-24 | G4: ENE-25 | H4: FEB-25 | I4: MAR-25 | J4: ABR | K4: Mayo | L4: Junio | M4: julio | N4: Agosto | O4: Sept | P4: Total/Mes | R4: DIC-25 | S4: DIC-27
C5: INGRESOS PROPIOS | K5: ='ingreso-mayo'!D5 -> 0 | L5: ='ingreso-junio'!D5 -> 0 | M5: =julio!D5:D51 -> 0 | N5: =agosto!D5 -> 0
C6: 1.-IMPUESTOS | K6: ='ingreso-mayo'!D6 -> 0 | L6: ='ingreso-junio'!D6 -> 0 | M6: =julio!D6:D52 -> 0 | N6: =agosto!D6 -> 0 | P6: =SUM(D6:L6) -> 0
C7: 1.1.-Predial | F7: 1743 | K7: ='ingreso-mayo'!D7 -> 0 | L7: ='ingreso-junio'!D7 -> 0 | M7: =julio!D7:D53 -> 0 | N7: =agosto!D7 -> 0 | P7: =SUM(D7:O7) -> 1743
C8: 1.2.-Sobre espectaculos publicos | K8: ='ingreso-mayo'!D8 -> 0 | L8: ='ingreso-junio'!D8 -> 2500 | M8: =julio!D8:D54 -> 0 | N8: =agosto!D8 -> 0 | P8: =SUM(D8:O8) -> 2500
C9: 1.3.-sobre adquisiciòn de inmuebles | K9: ='ingreso-mayo'!D9 -> 0 | L9: ='ingreso-junio'!D9 -> 0 | M9: =julio!D9:D55 -> 0 | N9: =agosto!D9 -> 0 | P9: =SUM(D9:L9) -> 0
C10: 2.- DERECHOS | K10: ='ingreso-mayo'!D10 -> 0 | L10: ='ingreso-junio'!D10 -> 0 | M10: =julio!D10:D56 -> 0 | N10: =agosto!D10 -> 0 | P10: =SUM(D10:L10) -> 0
C11: POR SERVICIOS PUBLICOS | K11: ='ingreso-mayo'!D11 -> 0 | L11: ='ingreso-junio'!D11 -> 0 | M11: =julio!D11:D57 -> 0 | N11: =agosto!D11 -> 0 | P11: =SUM(D11:L11) -> 0
C12: Derecho de piso | D12: 300 | E12: 300 | F12: 300 | G12: 600 | K12: ='ingreso-mayo'!D12 -> 4400 | L12: ='ingreso-junio'!D12 -> 0 | M12: =julio!D12:D58 -> 900 | N12: =agosto!D12 -> 9875 | O12: 3700 | P12: =SUM(D12:O12) -> 20375
C13: Servicio de pantiones | K13: ='ingreso-mayo'!D13 -> 0 | L13: ='ingreso-junio'!D13 -> 0 | M13: =julio!D13:D59 -> 0 | N13: =agosto!D13 -> 0 | P13: =SUM(D13:L13) -> 0
C14: Servicio de recolecciòn de basura | G14: 900 | H14: 1920 | I14: 1440 | K14: ='ingreso-mayo'!D14 -> 0 | L14: ='ingreso-junio'!D14 -> 0 | M14: =julio!D14:D60 -> 480 | N14: =agosto!D14 -> 0 | O14: 480 | P14: =SUM(D14:O14) -> 5220
C15: Por uso de Rastro publico | E15: 1900 | K15: ='ingreso-mayo'!D15 -> 0 | L15: ='ingreso-junio'!D15 -> 0 | M15: =julio!D15:D61 -> 0 | N15: =agosto!D15 -> 0 | P15: =SUM(D15:O15) -> 1900
C16: POR AUTORIZACIÒN Y LICENCIAS DIVERSAS | K16: ='ingreso-mayo'!D16 -> 0 | L16: ='ingreso-junio'!D16 -> 0 | M16: =julio!D16:D62 -> 0 | N16: =agosto!D16 -> 0 | P16: =SUM(D16:L16) -> 0
C17: Por uso de suelo | K17: ='ingreso-mayo'!D17 -> 0 | L17: ='ingreso-junio'!D17 -> 0 | M17: =julio!D17:D63 -> 0 | N17: =agosto!D17 -> 0 | P17: =SUM(D17:L17) -> 0
C18: Licencia de funcionamiento | D18: 450 | G18: 1890 | H18: 960 | I18: 480 | K18: ='ingreso-mayo'!D18 -> 480 | L18: ='ingreso-junio'!D18 -> 0 | M18: =julio!D18:D64 -> 480 | N18: =agosto!D18 -> 0 | O18: 1440 | P18: =SUM(D18:O18) -> 6180
C19: Por uso de la via publica | D19: 2250 | F19: 5100 | G19: 2340 | H19: 1440 | I19: 960 | J19: 960 | K19: ='ingreso-mayo'!D19 -> 1920 | L19: ='ingreso-junio'!D19 -> 480 | M19: =julio!D19:D65 -> 1440 | N19: =agosto!D19 -> 960 | O19: 1500 | P19: =SUM(D19:O19) -> 19350
C20: POR EXPEDICIÒN DE CERTYIF., CONSTANCIAS Y DUPLICADOS. | K20: ='ingreso-mayo'!D20 -> 0 | L20: ='ingreso-junio'!D20 -> 0 | M20: =julio!D20:D66 -> 0 | N20: =agosto!D20 -> 0 | P20: =SUM(D20:L20) -> 0
C21: Certificados | K21: ='ingreso-mayo'!D21 -> 0 | L21: ='ingreso-junio'!D21 -> 0 | M21: =julio!D21:D67 -> 0 | N21: =agosto!D21 -> 0 | P21: =SUM(D21:L21) -> 0
C22: Constancias | D22: 500 | F22: 900 | I22: 500 | K22: ='ingreso-mayo'!D22 -> 0 | L22: ='ingreso-junio'!D22 -> 0 | M22: =julio!D22:D68 -> 0 | N22: =agosto!D22 -> 0 | P22: =SUM(D22:O22) -> 1900
C23: Duplicados | K23: ='ingreso-mayo'!D23 -> 0 | L23: ='ingreso-junio'!D23 -> 0 | M23: =julio!D23:D69 -> 0 | N23: =agosto!D23 -> 0 | P23: =SUM(D23:L23) -> 0
C24: Documentos de compra venta | K24: ='ingreso-mayo'!D24 -> 0 | L24: ='ingreso-junio'!D24 -> 0 | M24: =julio!D24:D70 -> 0 | N24: =agosto!D24 -> 0 | P24: =SUM(D24:L24) -> 0
C25: Otros derechos | K25: ='ingreso-mayo'!D25 -> 0 | L25: ='ingreso-junio'!D25 -> 0 | M25: =julio!D25:D71 -> 0 | N25: =agosto!D25 -> 0 | P25: =SUM(D25:L25) -> 0
C26: 3.- PRODUCTOS | K26: ='ingreso-mayo'!D26 -> 0 | L26: ='ingreso-junio'!D26 -> 0 | M26: =julio!D26:D72 -> 0 | N26: =agosto!D26 -> 0 | P26: =SUM(D26:L26) -> 0
C27: POR ENAJENACIÒN DE BIENES E INMUEBLES | K27: ='ingreso-mayo'!D27 -> 0 | L27: ='ingreso-junio'!D27 -> 0 | M27: =julio!D27:D73 -> 0 | N27: =agosto!D27 -> 0 | P27: =SUM(D27:L27) -> 0
C28: Panteon Municipal (Lotes y Nichos) | G28: 0 | H28: 500 | I28: 500 | J28: 5000 | K28: ='ingreso-mayo'!D28 -> 0 | L28: ='ingreso-junio'!D28 -> 9000 | M28: =julio!D28:D74 -> 3500 | N28: =agosto!D28 -> 0 | P28: =SUM(D28:O28) -> 18500
C29: Panteon Municipal (Boveda) | G29: 0 | I29: 2000 | J29: 500 | K29: ='ingreso-mayo'!D29 -> 0 | L29: ='ingreso-junio'!D29 -> 1500 | M29: =julio!D29:D75 -> 0 | N29: =agosto!D29 -> 3000 | O29: 500 | P29: =SUM(D29:O29) -> 7500
C30: Mercado publico y Locales Comerciales | G30: 0 | K30: ='ingreso-mayo'!D30 -> 0 | L30: ='ingreso-junio'!D30 -> 0 | M30: =julio!D30:D76 -> 0 | N30: =agosto!D30 -> 0 | P30: =SUM(D30:L30) -> 0
C31: Baños publicos | G31: 0 | K31: ='ingreso-mayo'!D31 -> 0 | L31: ='ingreso-junio'!D31 -> 0 | M31: =julio!D31:D77 -> 0 | N31: =agosto!D31 -> 0 | P31: =SUM(D31:L31) -> 0
C32: Otros Productos (Ferias Tradicioners) | K32: ='ingreso-mayo'!D32 -> 0 | L32: ='ingreso-junio'!D32 -> 0 | M32: =julio!D32:D78 -> 0 | N32: =agosto!D32 -> 0 | P32: =SUM(D32:L32) -> 0
C33: 4.- APROVECHAMIENTOS | K33: ='ingreso-mayo'!D33 -> 0 | L33: ='ingreso-junio'!D33 -> 0 | M33: =julio!D33:D79 -> 0 | N33: =agosto!D33 -> 0 | P33: =SUM(D33:L33) -> 0
C34: Rezagos | K34: ='ingreso-mayo'!D34 -> 0 | L34: ='ingreso-junio'!D34 -> 0 | M34: =julio!D34:D80 -> 0 | N34: =agosto!D34 -> 0 | P34: =SUM(D34:L34) -> 0
C35: Multas | K35: ='ingreso-mayo'!D35 -> 0 | L35: ='ingreso-junio'!D35 -> 0 | M35: =julio!D35:D81 -> 0 | N35: =agosto!D35 -> 0 | P35: =SUM(D35:L35) -> 0
B36: B | C36: INGRESOS POR PARTICIPACIÒN | K36: ='ingreso-mayo'!D36 -> 0 | L36: ='ingreso-junio'!D36 -> 0 | M36: =julio!D36:D82 -> 0 | N36: =agosto!D36 -> 0 | P36: =SUM(D36:L36) -> 0
C37: 5.- PARTICIPACIONES | K37: ='ingreso-mayo'!D37 -> 0 | L37: ='ingreso-junio'!D37 -> 0 | M37: =julio!D37:D83 -> 0 | N37: =agosto!D37 -> 0 | P37: =SUM(D37:L37) -> 0
C38: Fondo Municipal | D38: 456017.5 | E38: 456017.5 | F38: 456017.5 | G38: 456017.5 | H38: 456017.5 | I38: 456017.5 | J38: 456017.5 | K38: ='ingreso-mayo'!D38 -> 456017.5 | L38: ='ingreso-junio'!D38 -> 456017.51 | M38: =julio!D38:D84 -> 456017.51 | N38: =agosto!D38 -> 456017.51 | O38: 456017.51 | P38: =SUM(D38:O38) -> 5472210 | Q38: =SUM(P38:P39) -> 7286979.4
C39: Fondo Estatal | D39: 151230.82 | E39: 151230.82 | F39: 151230.82 | H39: 302460.47 | I39: 151230.92 | J39: 151230.92 | K39: ='ingreso-mayo'!D39 -> 151230.92 | L39: ='ingreso-junio'!D39 -> 151230.92 | M39: =julio!D39:D85 -> 151230.92 | N39: =agosto!D39 -> 151230.92 | O39: 151230.92 | P39: =SUM(D39:O39) -> 1814769.4
C40: Complemento de Fondo Estatal | K40: ='ingreso-mayo'!D40 -> 0 | L40: ='ingreso-junio'!D40 -> 0 | M40: =julio!D40:D86 -> 0 | N40: =agosto!D40 -> 0 | P40: =SUM(D40:L40) -> 0
C41: Fondo Municipal de Prima Vacacional | K41: ='ingreso-mayo'!D41 -> 0 | L41: ='ingreso-junio'!D41 -> 0 | M41: =julio!D41:D87 -> 0 | N41: =agosto!D41 -> 0 | P41: =SUM(D41:L41) -> 0
...

Sheet INGRESO-OCT
C2: INGRESO GENERAL
B4: A | C4: CONCEPTO | D4: SUB- TOTAL | E4: TOTAL | F4: % /RUBRO | G4: % GLOBAL
C5: INGRESOS PROPIOS
C6: 1.-IMPUESTOS
C7: 1.1.-Predial
C8: 1.2.-Sobre espectaculos publicos
C9: 1.3.-sobre adquisiciòn de inmuebles
C10: 2.- DERECHOS | E10: =SUM(D11:D25) -> 3500 | F10: =SUM(F11:F25) -> 91.428571 | G10: =(E10/E51)*100 -> 0.57306748
C11: POR SERVICIOS PUBLICOS
C12: Derecho de piso | D12: 300
C13: Servicio de pantiones
C14: Servicio de recolecciòn de basura | F14: =D14/E10*100 -> 0
C15: Por uso de Rastro publico
C16: POR AUTORIZACIÒN Y LICENCIAS DIVERSAS
C17: Por uso de suelo
C18: Licencia de funcionamiento | D18: 450 | F18: =D18/E10*100 -> 12.857143
C19: Por uso de la via publica | D19: 2250 | F19: =D19/E10*100 -> 64.285714
C20: POR EXPEDICIÒN DE CERTYIF., CONSTANCIAS Y DUPLICADOS.
C21: Certificados
C22: Constancias | D22: 500 | F22: =D22/E10*100 -> 14.285714
C23: Duplicados
C24: Documentos de compra venta
C25: Otros derechos
C26: 3.- PRODUCTOS | F26: =SUM(F27:F32) -> #DIV/0! | G26: =(E26/E51)*100 -> 0
C27: POR ENAJENACIÒN DE BIENES E INMUEBLES
C28: Pantion Municipal (Lotes y Nichos) | F28: =D28/E26*100 -> #DIV/0!
C29: Pantion Municipal (Boveda) | F29: =D29/E26*100 -> #DIV/0!
C30: Mercado publico y Locales Comerciales
C31: Baños publicos
C32: Otros Productos (Ferias Tradicioners)
C33: 4.- APROVECHAMIENTOS
C34: Rezagos
C35: Multas
B36: B | C36: INGRESOS POR PARTICIPACIÒN
C37: 5.- PARTICIPACIONES | E37: =SUM(D38:D41) -> 607248.32 | G37: =E37/E51*100 -> 99.426933
C38: Fondo Municipal | D38: 456017.5
C39: Fondo Estatal | D39: 151230.82
C40: Complemento de Fondo Estatal
C41: Fondo Municipal de Prima Vacacional
B42: C | C42: INGRESOS EXTRAORDINARIOS
...

Sheet INGRESO-NOV
C2: INGRESO GENERAL
B4: A | C4: CONCEPTO | D4: SUB- TOTAL | E4: TOTAL | F4: % /RUBRO | G4: % GLOBAL
C5: INGRESOS PROPIOS
C6: 1.-IMPUESTOS
C7: 1.1.-Predial
C8: 1.2.-Sobre espectaculos publicos
C9: 1.3.-sobre adquisiciòn de inmuebles
C10: 2.- DERECHOS | E10: =SUM(D11:D25) -> 2200 | F10: =SUM(F11:F25) -> 86.363636 | G10: =(E10/E51)*100 -> 0.36098221
C11: POR SERVICIOS PUBLICOS
C12: Derecho de piso | D12: 300
C13: Servicio de pantiones
C14: Servicio de recolecciòn de basura | F14: =D14/E10*100 -> 0
C15: Por uso de Rastro publico
C16: POR AUTORIZACIÒN Y LICENCIAS DIVERSAS
C17: Por uso de suelo
C18: Licencia de funcionamiento | F18: =D18/E10*100 -> 0
C19: Por uso de la via publica | D19: 1900 | F19: =D19/E10*100 -> 86.363636
C20: POR EXPEDICIÒN DE CERTYIF., CONSTANCIAS Y DUPLICADOS.
C21: Certificados
C22: Constancias | F22: =D22/E10*100 -> 0
C23: Duplicados
C24: Documentos de compra venta
C25: Otros derechos
C26: 3.- PRODUCTOS | F26: =SUM(F27:F32) -> #DIV/0! | G26: =(E26/E51)*100 -> 0
C27: POR ENAJENACIÒN DE BIENES E INMUEBLES
C28: Pantion Municipal (Lotes y Nichos) | F28: =D28/E26*100 -> #DIV/0!
C29: Pantion Municipal (Boveda) | F29: =D29/E26*100 -> #DIV/0!
C30: Mercado publico y Locales Comerciales
C31: Baños publicos
C32: Otros Productos (Ferias Tradicioners)
C33: 4.- APROVECHAMIENTOS
C34: Rezagos
C35: Multas
B36: B | C36: INGRESOS POR PARTICIPACIÒN
C37: 5.- PARTICIPACIONES | E37: =SUM(D38:D41) -> 607248.32 | G37: =E37/E51*100 -> 99.639018
C38: Fondo Municipal | D38: 456017.5
C39: Fondo Estatal | D39: 151230.82
C40: Complemento de Fondo Estatal
C41: Fondo Municipal de Prima Vacacional
B42: C | C42: INGRESOS EXTRAORDINARIOS
...

Sheet INGRESO-DICIEMBRE
C2: INGRESO GENERAL
B4: A | C4: CONCEPTO | D4: SUB- TOTAL | E4: TOTAL | F4: % /RUBRO | G4: % GLOBAL
C5: INGRESOS PROPIOS
C6: 1.-IMPUESTOS | E6: =SUM(D7:D9) -> 1743
C7: 1.1.-Predial
C8: 1.2.-Sobre espectaculos publicos | D8: 1743
C9: 1.3.-sobre adquisiciòn de inmuebles
C10: 2.- DERECHOS | E10: =SUM(D11:D25) -> 6300 | F10: =SUM(F11:F25) -> 95.238095 | G10: =(E10/E51)*100 -> 1.0239052
C11: POR SERVICIOS PUBLICOS
C12: Derecho de piso | D12: 300
C13: Servicio de pantiones
C14: Servicio de recolecciòn de basura | F14: =D14/E10*100 -> 0
C15: Por uso de Rastro publico
C16: POR AUTORIZACIÒN Y LICENCIAS DIVERSAS
C17: Por uso de suelo
C18: Licencia de funcionamiento | F18: =D18/E10*100 -> 0
C19: Por uso de la via publica | D19: 5100 | F19: =D19/E10*100 -> 80.952381
C20: POR EXPEDICIÒN DE CERTYIF., CONSTANCIAS Y DUPLICADOS.
C21: Certificados
C22: Constancias | D22: 900 | F22: =D22/E10*100 -> 14.285714
C23: Duplicados
C24: Documentos de compra venta
C25: Otros derechos
C26: 3.- PRODUCTOS | F26: =SUM(F27:F32) -> #DIV/0! | G26: =(E26/E51)*100 -> 0
C27: POR ENAJENACIÒN DE BIENES E INMUEBLES
C28: Pantion Municipal (Lotes y Nichos) | F28: =D28/E26*100 -> #DIV/0!
C29: Pantion Municipal (Boveda) | F29: =D29/E26*100 -> #DIV/0!
C30: Mercado publico y Locales Comerciales
C31: Baños publicos
C32: Otros Productos (Ferias Tradicioners)
C33: 4.- APROVECHAMIENTOS
C34: Rezagos
C35: Multas
B36: B | C36: INGRESOS POR PARTICIPACIÒN
C37: 5.- PARTICIPACIONES | E37: =SUM(D38:D41) -> 607248.32 | G37: =E37/E51*100 -> 98.692814
C38: Fondo Municipal | D38: 456017.5
C39: Fondo Estatal | D39: 151230.82
C40: Complemento de Fondo Estatal
C41: Fondo Municipal de Prima Vacacional
B42: C | C42: INGRESOS EXTRAORDINARIOS
...

Sheet ingreso -enero
C2: INGRESO GENERAL
B4: A | C4: CONCEPTO | D4: SUB- TOTAL | E4: TOTAL | F4: % /RUBRO | G4: % GLOBAL
C5: INGRESOS PROPIOS
C6: 1.-IMPUESTOS
C7: 1.1.-Predial
C8: 1.2.-Sobre espectaculos publicos
C9: 1.3.-sobre adquisiciòn de inmuebles
C10: 2.- DERECHOS | E10: =SUM(D11:D25) -> 5730 | F10: =SUM(F11:F25) -> 89.528796 | G10: =(E10/E51)*100 -> 1.240938
C11: POR SERVICIOS PUBLICOS
C12: Derecho de piso | D12: 600
C13: Servicio de pantiones
C14: Servicio de recolecciòn de basura | D14: 900 | F14: =D14/E10*100 -> 15.706806
C15: Por uso de Rastro publico
C16: POR AUTORIZACIÒN Y LICENCIAS DIVERSAS
C17: Por uso de suelo
C18: Licencia de funcionamiento | D18: 1890 | F18: =D18/E10*100 -> 32.984293
C19: Por uso de la via publica | D19: 2340 | F19: =D19/E10*100 -> 40.837696
C20: POR EXPEDICIÒN DE CERTYIF., CONSTANCIAS Y DUPLICADOS.
C21: Certificados
C22: Constancias | F22: =D22/E10*100 -> 0
C23: Duplicados
C24: Documentos de compra venta
C25: Otros derechos
C26: 3.- PRODUCTOS | F26: =SUM(F27:F32) -> #DIV/0! | G26: =(E26/E51)*100 -> 0
C27: POR ENAJENACIÒN DE BIENES E INMUEBLES
C28: Pantion Municipal (Lotes y Nichos) | D28: 0 | F28: =D28/E26*100 -> #DIV/0!
C29: Pantion Municipal (Boveda) | D29: 0 | F29: =D29/E26*100 -> #DIV/0!
C30: Mercado publico y Locales Comerciales | D30: 0
C31: Baños publicos | D31: 0
C32: Otros Productos (Ferias Tradicioners)
C33: 4.- APROVECHAMIENTOS
C34: Rezagos
C35: Multas
B36: B | C36: INGRESOS POR PARTICIPACIÒN
C37: 5.- PARTICIPACIONES | E37: =SUM(D38:D41) -> 456017.5 | G37: =E37/E51*100 -> 98.759062
C38: Fondo Municipal | D38: 456017.5
C39: Fondo Estatal
C40: Complemento de Fondo Estatal
C41: Fondo Municipal de Prima Vacacional
B42: C | C42: INGRESOS EXTRAORDINARIOS
...

Sheet ingreso-febrero
C2: INGRESO GENERAL
B4: A | C4: CONCEPTO | D4: SUB- TOTAL | E4: TOTAL | F4: % /RUBRO | G4: % GLOBAL
C5: INGRESOS PROPIOS
C6: 1.-IMPUESTOS
C7: 1.1.-Predial
C8: 1.2.-Sobre espectaculos publicos
C9: 1.3.-sobre adquisiciòn de inmuebles
C10: 2.- DERECHOS | E10: =SUM(D11:D25) -> 4320 | F10: =SUM(F11:F25) -> 100 | G10: =(E10/E51)*100 -> 0.48459723
C11: POR SERVICIOS PUBLICOS
C12: Derecho de piso
C13: Servicio de pantiones
C14: Servicio de recolecciòn de basura | D14: 1920 | F14: =D14/E10*100 -> 44.444444
C15: Por uso de Rastro publico
C16: POR AUTORIZACIÒN Y LICENCIAS DIVERSAS
C17: Por uso de suelo
C18: Licencia de funcionamiento | D18: 960 | F18: =D18/E10*100 -> 22.222222
C19: Por uso de la via publica | D19: 1440 | F19: =D19/E10*100 -> 33.333333
C20: POR EXPEDICIÒN DE CERTYIF., CONSTANCIAS Y DUPLICADOS.
C21: Certificados
C22: Constancias | F22: =D22/E10*100 -> 0
C23: Duplicados
C24: Documentos de compra venta
C25: Otros derechos
C26: 3.- PRODUCTOS | E26: =SUM(D27:D35) -> 500 | F26: =SUM(F27:F32) -> 100 | G26: =(E26/E51)*100 -> 0.056087642
C27: POR ENAJENACIÒN DE BIENES E INMUEBLES
C28: Pantion Municipal (Lotes y Nichos) | D28: 500 | F28: =D28/E26*100 -> 100
C29: Pantion Municipal (Boveda) | F29: =D29/E26*100 -> 0
C30: Mercado publico y Locales Comerciales
C31: Baños publicos
C32: Otros Productos (Ferias Tradicioners)
C33: 4.- APROVECHAMIENTOS
C34: Rezagos
C35: Multas
B36: B | C36: INGRESOS POR PARTICIPACIÒN
C37: 5.- PARTICIPACIONES | E37: =SUM(D38:D41) -> 758477.97 | F37: =SUM(F38:F41) -> 100 | G37: =E37/E51*100 -> 85.082482
C38: Fondo Municipal | D38: 456017.5 | F38: =D38/E37*100 -> 60.122709
C39: Fondo Estatal | D39: 302460.47 | F39: =D39/E37*100 -> 39.877291
C40: Complemento de Fondo Estatal
C41: Fondo Municipal de Prima Vacacional
B42: C | C42: INGRESOS EXTRAORDINARIOS
...

Sheet ingreso-marzo
C2: INGRESO GENERAL
B4: A | C4: CONCEPTO | D4: SUB- TOTAL | E4: TOTAL | F4: % /RUBRO | G4: % GLOBAL
C5: INGRESOS PROPIOS
C6: 1.-IMPUESTOS
C7: 1.1.-Predial
C8: 1.2.-Sobre espectaculos publicos
C9: 1.3.-sobre adquisiciòn de inmuebles
C10: 2.- DERECHOS | E10: =SUM(D11:D25) -> 3380 | F10: =SUM(F11:F25) -> 100 | G10: =(E10/E51)*100 -> 0.53188692
C11: POR SERVICIOS PUBLICOS
C12: Derecho de piso
C13: Servicio de pantiones
C14: Servicio de recolecciòn de basura | D14: 1440 | F14: =D14/E10*100 -> 42.60355
C15: Por uso de Rastro publico
C16: POR AUTORIZACIÒN Y LICENCIAS DIVERSAS
C17: Por uso de suelo
C18: Licencia de funcionamiento | D18: 480 | F18: =D18/E10*100 -> 14.201183
C19: Por uso de la via publica | D19: 960 | F19: =D19/E10*100 -> 28.402367
C20: POR EXPEDICIÒN DE CERTYIF., CONSTANCIAS Y DUPLICADOS.
C21: Certificados
C22: Constancias | D22: 500 | F22: =D22/E10*100 -> 14.792899
C23: Duplicados
C24: Documentos de compra venta
C25: Otros derechos
C26: 3.- PRODUCTOS | E26: =SUM(D27:D32) -> 2500 | F26: =SUM(F27:F32) -> 100 | G26: =(E26/E51)*100 -> 0.39340749
C27: POR ENAJENACIÒN DE BIENES E INMUEBLES
C28: Pantion Municipal (Lotes y Nichos) | D28: 500 | F28: =D28/E26*100 -> 20
C29: Pantion Municipal (Boveda) | D29: 2000 | F29: =D29/E26*100 -> 80
C30: Mercado publico y Locales Comerciales
C31: Baños publicos
C32: Otros Productos (Ferias Tradicioners)
C33: 4.- APROVECHAMIENTOS
C34: Rezagos
C35: Multas
B36: B | C36: INGRESOS POR PARTICIPACIÒN
C37: 5.- PARTICIPACIONES | E37: =SUM(D38:D41) -> 607248.42 | G37: =E37/E51*100 -> 95.558429
C38: Fondo Municipal | D38: 456017.5
C39: Fondo Estatal | D39: 151230.92
C40: Complemento de Fondo Estatal
C41: Fondo Municipal de Prima Vacacional
B42: C | C42: INGRESOS EXTRAORDINARIOS
...

Sheet ingreso-abril
C2: INGRESO GENERAL
B4: A | C4: CONCEPTO | D4: SUB- TOTAL | E4: TOTAL | F4: % /RUBRO | G4: % GLOBAL
C5: INGRESOS PROPIOS
C6: 1.-IMPUESTOS | E6: =SUM(D7:D9) -> 0
C7: 1.1.-Predial
C8: 1.2.-Sobre espectaculos publicos
C9: 1.3.-sobre adquisiciòn de inmuebles
C10: 2.- DERECHOS | E10: =SUM(D11:D25) -> 960 | F10: =SUM(F11:F25) -> 100 | G10: =(E10/E51)*100 -> 0.14913585
C11: POR SERVICIOS PUBLICOS
C12: 2.1.-Derecho de piso
C13: 2.2.-Servicio de pantiones
C14: 2.3.-Servicio de recolecciòn de basura | F14: =D14/E10*100 -> 0
C15: 2.4.-Por uso de Rastro publico
C16: POR AUTORIZACIÒN Y LICENCIAS DIVERSAS
C17: 2.5.-Por uso de suelo
C18: 2.6.-Licencia de funcionamiento | F18: =D18/E10*100 -> 0
C19: 2.7.-Por uso de la via publica | D19: 960 | F19: =D19/E10*100 -> 100
C20: POR EXPEDICIÒN DE CERTYIF., CONSTANCIAS Y DUPLICADOS.
C21: 2.8.-Certificados
C22: 2.9.-Constancias | F22: =D22/E10*100 -> 0
C23: 2.10.-Duplicados
C24: 2.11.-Documentos de compra venta
C25: 2.12.-Otros derechos
C26: 3.- PRODUCTOS | E26: =SUM(D27:D32) -> 5500 | F26: =SUM(F27:F32) -> 100 | G26: =(E26/E51)*100 -> 0.85442412
C27: POR ENAJENACIÒN DE BIENES E INMUEBLES
C28: 3.1.-Pantion Municipal (Lotes y Nichos) | D28: 5000 | F28: =D28/E26*100 -> 90.909091
C29: 3.2.-Pantion Municipal (Boveda) | D29: 500 | F29: =D29/E26*100 -> 9.0909091
C30: 3.3.-Mercado publico y Locales Comerciales
C31: 3.4.-Baños publicos
C32: 3.5.-Otros Productos (Ferias Tradicioners)
C33: 4.- APROVECHAMIENTOS
C34: 4.1.-Rezagos
C35: 4.2.-Multas
B36: B | C36: INGRESOS POR PARTICIPACIÒN
C37: 5.- PARTICIPACIONES | E37: =SUM(D38:D41) -> 607248.42 | G37: =E37/E51*100 -> 94.335945
C38: 5.1.-Fondo Municipal | D38: 456017.5
C39: 5.2.-Fondo Estatal | D39: 151230.92
C40: 5.3.-Complemento de Fondo Estatal
C41: 5.4.-Fondo Municipal de Prima Vacacional
B42: C | C42: INGRESOS EXTRAORDINARIOS
...

Sheet ingreso-mayo
C2: INGRESO GENERAL
B4: A | C4: CONCEPTO | D4: SUB- TOTAL | E4: TOTAL | F4: % /RUBRO | G4: % GLOBAL
C5: INGRESOS PROPIOS
C6: 1.-IMPUESTOS | E6: =SUM(D7:D9) -> 0
C7: 1.1.-Predial
C8: 1.2.-Sobre espectaculos publicos
C9: 1.3.-sobre adquisiciòn de inmuebles
C10: 2.- DERECHOS | E10: =SUM(D11:D25) -> 6800 | F10: =SUM(F11:F25) -> 35.294118 | G10: =(E10/E51)*100 -> 1.1074045
C11: POR SERVICIOS PUBLICOS
C12: 2.1.-Derecho de piso | D12: 4400
C13: 2.2.-Servicio de pantiones
C14: 2.3.-Servicio de recolecciòn de basura | F14: =D14/E10*100 -> 0
C15: 2.4.-Por uso de Rastro publico
C16: POR AUTORIZACIÒN Y LICENCIAS DIVERSAS
C17: 2.5.-Por uso de suelo
C18: 2.6.-Licencia de funcionamiento | D18: 480 | F18: =D18/E10*100 -> 7.0588235
C19: 2.7.-Por uso de la via publica | D19: 1920 | F19: =D19/E10*100 -> 28.235294
C20: POR EXPEDICIÒN DE CERTYIF., CONSTANCIAS Y DUPLICADOS.
C21: 2.8.-Certificados
C22: 2.9.-Constancias | F22: =D22/E10*100 -> 0
C23: 2.10.-Duplicados
C24: 2.11.-Documentos de compra venta
C25: 2.12.-Otros derechos
C26: 3.- PRODUCTOS | F26: =SUM(F27:F32) -> #DIV/0! | G26: =(E26/E51)*100 -> 0
C27: POR ENAJENACIÒN DE BIENES E INMUEBLES
C28: 3.1.-Pantion Municipal (Lotes y Nichos) | F28: =D28/E26*100 -> #DIV/0!
C29: 3.2.-Pantion Municipal (Boveda) | F29: =D29/E26*100 -> #DIV/0!
C30: 3.3.-Mercado publico y Locales Comerciales
C31: 3.4.-Baños publicos
C32: 3.5.-Otros Productos (Ferias Tradicioners)
C33: 4.- APROVECHAMIENTOS
C34: 4.1.-Rezagos
C35: 4.2.-Multas
B36: B | C36: INGRESOS POR PARTICIPACIÒN
C37: 5.- PARTICIPACIONES | E37: =SUM(D38:D41) -> 607248.42 | G37: =E37/E51*100 -> 98.892595
C38: 5.1.-Fondo Municipal | D38: 456017.5
C39: 5.2.-Fondo Estatal | D39: 151230.92
C40: 5.3.-Complemento de Fondo Estatal
C41: 5.4.-Fondo Municipal de Prima Vacacional
B42: C | C42: INGRESOS EXTRAORDINARIOS
...

Sheet ingreso-junio
C2: INGRESO GENERAL
B4: A | C4: CONCEPTO | D4: SUB- TOTAL | E4: TOTAL | F4: % /RUBRO | G4: % GLOBAL
C5: INGRESOS PROPIOS
C6: 1.-IMPUESTOS | E6: =SUM(D7:D9) -> 2500
C7: 1.1.-Predial
C8: 1.2.-Sobre espectáculos públicos | D8: 2500
C9: 1.3.-sobre adquisición de inmuebles
C10: 2.- DERECHOS | E10: =SUM(D11:D25) -> 480 | F10: =SUM(F11:F25) -> 100 | G10: =(E10/E51)*100 -> 0.077328503
C11: POR SERVICIOS PUBLICOS
C12: 2.1.-Derecho de piso
C13: 2.2.-Servicio de panteones
C14: 2.3.-Servicio de recolección de basura | F14: =D14/E10*100 -> 0
C15: 2.4.-Por uso de Rastro publico
C16: POR AUTORIZACIÒN Y LICENCIAS DIVERSAS
C17: 2.5.-Por uso de suelo
C18: 2.6.-Licencia de funcionamiento | F18: =D18/E10*100 -> 0
C19: 2.7.-Por uso de la vía publica | D19: 480 | F19: =D19/E10*100 -> 100
C20: POR EXPEDICIÒN DE CERTYIF., CONSTANCIAS Y DUPLICADOS.
C21: 2.8.-Certificados
C22: 2.9.-Constancias | F22: =D22/E10*100 -> 0
C23: 2.10.-Duplicados
C24: 2.11.-Documentos de compra venta
C25: 2.12.-Otros derechos
C26: 3.- PRODUCTOS | E26: =SUM(D27:D32) -> 10500 | F26: =SUM(F27:F32) -> 100 | G26: =(E26/E51)*100 -> 1.691561
C27: POR ENAJENACIÒN DE BIENES E INMUEBLES
C28: 3.1.-Panteòn Municipal (Lotes y Nichos) | D28: 9000 | F28: =D28/E26*100 -> 85.714286
C29: 3.2.-Panteon Municipal (Bóveda) | D29: 1500 | F29: =D29/E26*100 -> 14.285714
C30: 3.3.-Mercado publico y Locales Comerciales
C31: 3.4.-Baños públicos
C32: 3.5.-Otros Productos (Ferias Tradiciones)
C33: 4.- APROVECHAMIENTOS
C34: 4.1.-Rezagos
C35: 4.2.-Multas
B36: B | C36: INGRESOS POR PARTICIPACIÒN
C37: 5.- PARTICIPACIONES | E37: =SUM(D38:D41) -> 607248.43 | G37: =E37/E51*100 -> 97.828358
C38: 5.1.-Fondo Municipal | D38: 456017.51
C39: 5.2.-Fondo Estatal | D39: 151230.92
C40: 5.3.-Complemento de Fondo Estatal
C41: 5.4.-Fondo Municipal de Prima Vacacional
B42: C | C42: INGRESOS EXTRAORDINARIOS
...

Sheet julio
C2: INGRESO GENERAL
B4: A | C4: CONCEPTO | D4: SUB- TOTAL | E4: TOTAL | F4: % /RUBRO | G4: % GLOBAL
C5: INGRESOS PROPIOS
C6: 1.-IMPUESTOS | E6: =SUM(D7:D9) -> 0
C7: 1.1.-Predial
C8: 1.2.-Sobre espectáculos públicos
C9: 1.3.-sobre adquisición de inmuebles
C10: 2.- DERECHOS | E10: =SUM(D11:D25) -> 3300 | F10: =SUM(F11:F25) -> 72.727273 | G10: =(E10/E51)*100 -> 0.53741689
C11: POR SERVICIOS PUBLICOS
C12: 2.1.-Derecho de piso | D12: 900
C13: 2.2.-Servicio de panteones
C14: 2.3.-Servicio de recolección de basura | D14: 480 | F14: =D14/E10*100 -> 14.545455
C15: 2.4.-Por uso de Rastro publico
C16: POR AUTORIZACIÒN Y LICENCIAS DIVERSAS
C17: 2.5.-Por uso de suelo
C18: 2.6.-Licencia de funcionamiento | D18: 480 | F18: =D18/E10*100 -> 14.545455
C19: 2.7.-Por uso de la vía publica | D19: 1440 | F19: =D19/E10*100 -> 43.636364
C20: POR EXPEDICIÒN DE CERTYIF., CONSTANCIAS Y DUPLICADOS.
C21: 2.8.-Certificados
C22: 2.9.-Constancias | F22: =D22/E10*100 -> 0
C23: 2.10.-Duplicados
C24: 2.11.-Documentos de compra venta
C25: 2.12.-Otros derechos
C26: 3.- PRODUCTOS | E26: =SUM(D27:D32) -> 3500 | F26: =SUM(F27:F32) -> 100 | G26: =(E26/E51)*100 -> 0.56998761
C27: POR ENAJENACIÒN DE BIENES E INMUEBLES
C28: 3.1.-Panteòn Municipal (Lotes y Nichos) | D28: 3500 | F28: =D28/E26*100 -> 100
C29: 3.2.-Panteon Municipal (Bóveda) | F29: =D29/E26*100 -> 0
C30: 3.3.-Mercado publico y Locales Comerciales
C31: 3.4.-Baños públicos
C32: 3.5.-Otros Productos (Ferias Tradiciones)
C33: 4.- APROVECHAMIENTOS
C34: 4.1.-Rezagos
C35: 4.2.-Multas
B36: B | C36: INGRESOS POR PARTICIPACIÒN
C37: 5.- PARTICIPACIONES | E37: =SUM(D38:D41) -> 607248.43 | G37: =E37/E51*100 -> 98.892595
C38: 5.1.-Fondo Municipal | D38: 456017.51
C39: 5.2.-Fondo Estatal | D39: 151230.92
C40: 5.3.-Complemento de Fondo Estatal
C41: 5.4.-Fondo Municipal de Prima Vacacional
B42: C | C42: INGRESOS EXTRAORDINARIOS
...

Sheet agosto
C2: INGRESO GENERAL
B4: A | C4: CONCEPTO | D4: SUB- TOTAL | E4: TOTAL | F4: % /RUBRO | G4: % GLOBAL
C5: INGRESOS PROPIOS
C6: 1.-IMPUESTOS | E6: =SUM(D7:D9) -> 0
C7: 1.1.-Predial
C8: 1.2.-Sobre espectáculos públicos
C9: 1.3.-sobre adquisición de inmuebles
C10: 2.- DERECHOS | E10: =SUM(D11:D25) -> 10835 | F10: =SUM(F11:F25) -> 8.8601754 | G10: =(E10/E51)*100 -> 1.7445321
C11: POR SERVICIOS PUBLICOS
C12: 2.1.-Derecho de piso | D12: 9875
C13: 2.2.-Servicio de panteones
C14: 2.3.-Servicio de recolección de basura | F14: =D14/E10*100 -> 0
C15: 2.4.-Por uso de Rastro publico
C16: POR AUTORIZACIÒN Y LICENCIAS DIVERSAS
C17: 2.5.-Por uso de suelo
C18: 2.6.-Licencia de funcionamiento | F18: =D18/E10*100 -> 0
C19: 2.7.-Por uso de la vía publica | D19: 960 | F19: =D19/E10*100 -> 8.8601754
C20: POR EXPEDICIÒN DE CERTYIF., CONSTANCIAS Y DUPLICADOS.
C21: 2.8.-Certificados
C22: 2.9.-Constancias | F22: =D22/E10*100 -> 0
C23: 2.10.-Duplicados
C24: 2.11.-Documentos de compra venta
C25: 2.12.-Otros derechos
C26: 3.- PRODUCTOS | E26: =SUM(D27:D32) -> 3000 | F26: =SUM(F27:F32) -> 100 | G26: =(E26/E51)*100 -> 0.48302689
C27: POR ENAJENACIÒN DE BIENES E INMUEBLES
C28: 3.1.-Panteòn Municipal (Lotes y Nichos) | F28: =D28/E26*100 -> 0
C29: 3.2.-Panteon Municipal (Bóveda) | D29: 3000 | F29: =D29/E26*100 -> 100
C30: 3.3.-Mercado publico y Locales Comerciales
C31: 3.4.-Baños públicos
C32: 3.5.-Otros Productos (Ferias Tradiciones)
C33: 4.- APROVECHAMIENTOS
C34: 4.1.-Rezagos
C35: 4.2.-Multas
B36: B | C36: INGRESOS POR PARTICIPACIÒN
C37: 5.- PARTICIPACIONES | E37: =SUM(D38:D41) -> 607248.43 | G37: =E37/E51*100 -> 97.772441
C38: 5.1.-Fondo Municipal | D38: 456017.51
C39: 5.2.-Fondo Estatal | D39: 151230.92
C40: 5.3.-Complemento de Fondo Estatal
C41: 5.4.-Fondo Municipal de Prima Vacacional
B42: C | C42: INGRESOS EXTRAORDINARIOS
...

Sheet Septiembre
C2: INGRESO GENERAL
B4: A | C4: CONCEPTO | D4: SUB- TOTAL | E4: TOTAL | F4: % /RUBRO | G4: % GLOBAL
C5: INGRESOS PROPIOS
C6: 1.-IMPUESTOS | E6: =SUM(D7:D9) -> 0
C7: 1.1.-Predial
C8: 1.2.-Sobre espectáculos públicos
C9: 1.3.-sobre adquisición de inmuebles
C10: 2.- DERECHOS | E10: =SUM(D11:D25) -> 7120 | F10: =SUM(F11:F25) -> 20.224719 | G10: =(E10/E51)*100 -> 1.1579713
C11: POR SERVICIOS PUBLICOS
C12: 2.1.-Derecho de piso
C13: 2.2.-Servicio de panteones | D13: 3700
C14: 2.3.-Servicio de recolección de basura | F14: =D14/E10*100 -> 0
C15: 2.4.-Por uso de Rastro publico | D15: 480
C16: POR AUTORIZACIÒN Y LICENCIAS DIVERSAS
C17: 2.5.-Por uso de suelo
C18: 2.6.-Licencia de funcionamiento | F18: =D18/E10*100 -> 0
C19: 2.7.-Por uso de la vía publica | D19: 1440 | F19: =D19/E10*100 -> 20.224719
C20: POR EXPEDICIÒN DE CERTYIF., CONSTANCIAS Y DUPLICADOS. | D20: 1500
C21: 2.8.-Certificados
C22: 2.9.-Constancias | F22: =D22/E10*100 -> 0
C23: 2.10.-Duplicados
C24: 2.11.-Documentos de compra venta
C25: 2.12.-Otros derechos
C26: 3.- PRODUCTOS | E26: =SUM(D27:D32) -> 500 | F26: =SUM(F27:F32) -> 0 | G26: =(E26/E51)*100 -> 0.08131821
C27: POR ENAJENACIÒN DE BIENES E INMUEBLES
C28: 3.1.-Panteòn Municipal (Lotes y Nichos) | F28: =D28/E26*100 -> 0
C29: 3.2.-Panteon Municipal (Bóveda) | F29: =D29/E26*100 -> 0
C30: 3.3.-Mercado publico y Locales Comerciales | D30: 500
C31: 3.4.-Baños públicos
C32: 3.5.-Otros Productos (Ferias Tradiciones)
C33: 4.- APROVECHAMIENTOS
C34: 4.1.-Rezagos
C35: 4.2.-Multas
B36: B | C36: INGRESOS POR PARTICIPACIÒN
C37: 5.- PARTICIPACIONES | E37: =SUM(D38:D41) -> 607248.43 | G37: =E37/E51*100 -> 98.76071
C38: 5.1.-Fondo Municipal
C39: 5.2.-Fondo Estatal | D39: 456017.51
C40: 5.3.-Complemento de Fondo Estatal | D40: 151230.92
C41: 5.4.-Fondo Municipal de Prima Vacacional
B42: C | C42: INGRESOS EXTRAORDINARIOS
...
